Workbook
Name prevWBS: '(細部)工作任務_甘特圖'!$A1048576
Name valuevx: 42.314159
Name WBS層級名稱: 'PLM001-Active'!$C$2:$C$1048576
Name 人員: 'PLM001-Active'!$K$2:$K$1048576
Name 工期: 'PLM001-Active'!$O$2:$O$1048576
Name 任務名稱: 'PLM001-Active'!$E$2:$E$1048576
Name 任務完成度: 'PLM001-Active'!$L$2:$L$1048576
Name 任務狀態: 'PLM001-Active'!$Q$2:$Q$1048576
Name 任務負責人: 'PLM001-Active'!$H$2:$H$1048576
Name 專案名稱: 'PLM001-Active'!$B$2:$B$1048576
Name 專案指派: 'PLM001-Active'!$I$2:$I$1048576
Name 專案負責人: 'PLM001-Active'!$D$2:$D$1048576
Name 專案編號: 'PLM001-Active'!$A$2:$A$1048576
Name 部門名稱: 'PLM001-Active'!$G$2:$G$1048576
Name 描述_延遲原因: 'PLM001-Active'!$F$2:$F$1048576
Name 結案日期: 'PLM001-Active'!$V$2:$V$1048576
Name 預計工時: 'PLM001-Active'!$P$2:$P$1048576
Name 預計結束日: 'PLM001-Active'!$N$2:$N$1048576
Name 預計開始日: 'PLM001-Active'!$M$2:$M$1048576
Name 實際工時: 'PLM001-Active'!$U$2:$U$1048576
Name 實際天數: 'PLM001-Active'!$T$2:$T$1048576
Name 實際完成日: 'PLM001-Active'!$S$2:$S$1048576
Name 實際開始日: 'PLM001-Active'!$R$2:$R$1048576

Sheet 總表
A1: 查詢範圍 | B1: 45658 | C1: 46044
A2: 研發一處
A3: 專案編號 | B3: 專案名稱 | D3: 專案負責人 | E3: 專案狀態 | F3: 預計起始日 | G3: 預計完成日 | H3: 實際開始日 | I3: 實際完成日 | J3: 預計設工時 | K3: 實際設計工時 | L3: 本週投入設工 | M3: 專案是否異常 | N3: 工況試煉送樣 (來源PLM) | O3: 異常說明 | P3: 需要的協助 | Q3: 預計完成日
A4: D250703R1 | B4: =VLOOKUP(A4,專案進度表!B:DT,2,FALSE) -> EPH連板電測治具 | C4: =VLOOKUP(A4,專案進度表!$B:$DT,4,FALSE) -> 研發一處 | D4: =VLOOKUP(A4,專案進度表!$B:$DT,5,FALSE) -> 賴慶樺 | E4: =VLOOKUP(A4,專案進度表!$B:$DT,6,FALSE) -> Active | F4: =VLOOKUP(A4,專案進度表!$B:$DT,7,FALSE) -> 45862.667 | G4: =VLOOKUP(A4,專案進度表!$B:$DT,8,FALSE) -> 46051.667 | H4: =IF(VLOOKUP(A4,專案進度表!$B:$DT,12,FALSE)=0,"",VLOOKUP(A4,專案進度表!$B:$DT,12,FALSE)) -> 45866 | I4: =IF(VLOOKUP(A4,專案進度表!$B:$DT,13,FALSE)=0,"",VLOOKUP(A4,專案進度表!$B:$DT,13,FALSE)) | J4: =IF(SUMIFS('PLM001-財務計算用'!$P:$P,'PLM001-財務計算用'!$A:$A,A4)=0,"未登入",SUMIFS('PLM001-財務計算用'!$P:$P,'PLM001-財務計算用'!$A:$A,A4)) -> 未登入 | K4: =SUMIFS('PLM002'!$K:$K,'PLM002'!$F:$F,$A4) -> 76 | L4: =IF(SUMIFS('PLM002'!$K:$K,'PLM002'!$F:$F,A4,'PLM002'!$J:$J,">="&$B$1,'PLM002'!$J:$J,"<="&$C$1)=0,"未投入",SUMIFS('PLM002'!$K:$K,'PLM002'!$F:$F,A4,'PLM002'!$J:$J,">="&$B$1,'PLM002'!$J:$J,"<="&$C$1)) -> 76 | M4: =VLOOKUP(A4,專案進度表!$B:$DT,18,FALSE) -> 專案即將異常 | N4: =IF(VLOOKUP(A4,'PLM014'!$B:$R,17,FALSE)=0,"",VLOOKUP(A4,'PLM014'!$B:$R,17,FALSE))
A5: M250301C1 | B5: =VLOOKUP(A5,專案進度表!B:DT,2,FALSE) -> 一體型電磁流量計北美多重防爆認證 | C5: =VLOOKUP(A5,專案進度表!$B:$DT,4,FALSE) -> 研發一處 | D5: =VLOOKUP(A5,專案進度表!$B:$DT,5,FALSE) -> 陳威諭 | E5: =VLOOKUP(A5,專案進度表!$B:$DT,6,FALSE) -> Active | F5: =VLOOKUP(A5,專案進度表!$B:$DT,7,FALSE) -> 45725.667 | G5: =VLOOKUP(A5,專案進度表!$B:$DT,8,FALSE) -> 46190.667 | H5: =IF(VLOOKUP(A5,專案進度表!$B:$DT,12,FALSE)=0,"",VLOOKUP(A5,專案進度表!$B:$DT,12,FALSE)) -> 45727 | I5: =IF(VLOOKUP(A5,專案進度表!$B:$DT,13,FALSE)=0,"",VLOOKUP(A5,專案進度表!$B:$DT,13,FALSE)) | J5: =IF(SUMIFS('PLM001-財務計算用'!$P:$P,'PLM001-財務計算用'!$A:$A,A5)=0,"未登入",SUMIFS('PLM001-財務計算用'!$P:$P,'PLM001-財務計算用'!$A:$A,A5)) -> 416 | K5: =SUMIFS('PLM002'!$K:$K,'PLM002'!$F:$F,$A5) -> 1314.5 | L5: =IF(SUMIFS('PLM002'!$K:$K,'PLM002'!$F:$F,A5,'PLM002'!$J:$J,">="&$B$1,'PLM002'!$J:$J,"<="&$C$1)=0,"未投入",SUMIFS('PLM002'!$K:$K,'PLM002'!$F:$F,A5,'PLM002'!$J:$J,">="&$B$1,'PLM002'!$J:$J,"<="&$C$1)) -> 1314.5 | M5: =VLOOKUP(A5,專案進度表!$B:$DT,18,FALSE) | N5: =IF(VLOOKUP(A5,'PLM014'!$B:$R,17,FALSE)=0,"",VLOOKUP(A5,'PLM014'!$B:$R,17,FALSE)) | O5: 9/26 CSA對於本安隔離柵的變壓器認定與過去的IECEX及NEPSI認定不同，會造成需要多3組zener 8W的保護零件，嚴重影響電路設計及空間需求。已請CSA工程師重新審視。 10/28 電路板發包打件、膠塊耐候性測試樣品CSA已收到。 11/4 膠體耐受性測試矽膠通過，黑色橡膠沒過，前蓋膠體更新後送件做耐壓測試。 11/14 目前合適的膠體正在確認。 11/14 電路板打件，預計11/19備料完成，12/3 打件回廠。
A6: M251201C1 | B6: =VLOOKUP(A6,專案進度表!B:DT,2,FALSE) -> GPX 申請UL-61010認證 | C6: =VLOOKUP(A6,專案進度表!$B:$DT,4,FALSE) -> 研發一處 | D6: =VLOOKUP(A6,專案進度表!$B:$DT,5,FALSE) -> 賴慶樺 | E6: =VLOOKUP(A6,專案進度表!$B:$DT,6,FALSE) -> Active | F6: =VLOOKUP(A6,專案進度表!$B:$DT,7,FALSE) -> 46019.667 | G6: =VLOOKUP(A6,專案進度表!$B:$DT,8,FALSE) -> 46111.667 | H6: =IF(VLOOKUP(A6,專案進度表!$B:$DT,12,FALSE)=0,"",VLOOKUP(A6,專案進度表!$B:$DT,12,FALSE)) -> 46024 | I6: =IF(VLOOKUP(A6,專案進度表!$B:$DT,13,FALSE)=0,"",VLOOKUP(A6,專案進度表!$B:$DT,13,FALSE)) | J6: =IF(SUMIFS('PLM001-財務計算用'!$P:$P,'PLM001-財務計算用'!$A:$A,A6)=0,"未登入",SUMIFS('PLM001-財務計算用'!$P:$P,'PLM001-財務計算用'!$A:$A,A6)) -> 未登入 | K6: =SUMIFS('PLM002'!$K:$K,'PLM002'!$F:$F,$A6) -> 36 | L6: =IF(SUMIFS('PLM002'!$K:$K,'PLM002'!$F:$F,A6,'PLM002'!$J:$J,">="&$B$1,'PLM002'!$J:$J,"<="&$C$1)=0,"未投入",SUMIFS('PLM002'!$K:$K,'PLM002'!$F:$F,A6,'PLM002'!$J:$J,">="&$B$1,'PLM002'!$J:$J,"<="&$C$1)) -> 36 | M6: =VLOOKUP(A6,專案進度表!$B:$DT,18,FALSE) -> 專案即將異常 | N6: =IF(VLOOKUP(A6,'PLM014'!$B:$R,17,FALSE)=0,"",VLOOKUP(A6,'PLM014'!$B:$R,17,FALSE))
A8: 技術中心
A9: 專案編號 | B9: 專案名稱 | D9: 專案負責人 | E9: 專案狀態 | F9: 預計起始日 | G9: 預計完成日 | H9: 實際開始日 | I9: 實際完成日 | J9: 預計設工時 | K9: 實際設計工時 | M9: 專案是否異常 | N9: 工況試煉送樣 | O9: 異常說明
A10: M230701R1 | B10: =VLOOKUP(A10,專案進度表!B:DT,2,FALSE) -> #N/A | C10: =VLOOKUP(A10,專案進度表!$B:$DT,4,FALSE) -> #N/A | D10: =VLOOKUP(A10,專案進度表!$B:$DT,5,FALSE) -> #N/A | E10: =VLOOKUP(A10,專案進度表!$B:$DT,6,FALSE) -> #N/A | F10: =VLOOKUP(A10,專案進度表!$B:$DT,7,FALSE) -> #N/A | G10: =VLOOKUP(A10,專案進度表!$B:$DT,8,FALSE) -> #N/A | H10: =VLOOKUP(A10,專案進度表!$B:$DT,12,FALSE) -> #N/A | I10: =VLOOKUP(A10,專案進度表!$B:$DT,13,FALSE) -> #N/A | J10: =IF(SUMIFS('PLM001-財務計算用'!$P:$P,'PLM001-財務計算用'!$A:$A,A10)=0,"未登入",SUMIFS('PLM001-財務計算用'!$P:$P,'PLM001-財務計算用'!$A:$A,A10)) -> 未登入 | K10: =SUMIFS('PLM002'!#REF!,'PLM002'!$F:$F,$A10) -> #REF! | M10: =VLOOKUP(A10,專案進度表!$B:$DT,18,FALSE) -> #N/A | N10: =IF(VLOOKUP(A10,'PLM014'!$B:$R,17,FALSE)=0,"",VLOOKUP(A10,'PLM014'!$B:$R,17,FALSE)) -> #N/A
A11: M230102R1 | B11: =VLOOKUP(A11,專案進度表!B:DT,2,FALSE) -> #N/A | C11: =VLOOKUP(A11,專案進度表!$B:$DT,4,FALSE) -> #N/A | D11: =VLOOKUP(A11,專案進度表!$B:$DT,5,FALSE) -> #N/A | E11: =VLOOKUP(A11,專案進度表!$B:$DT,6,FALSE) -> #N/A | F11: =VLOOKUP(A11,專案進度表!$B:$DT,7,FALSE) -> #N/A | G11: =VLOOKUP(A11,專案進度表!$B:$DT,8,FALSE) -> #N/A | H11: =VLOOKUP(A11,專案進度表!$B:$DT,12,FALSE) -> #N/A | I11: =VLOOKUP(A11,專案進度表!$B:$DT,13,FALSE) -> #N/A | J11: =IF(SUMIFS('PLM001-財務計算用'!$P:$P,'PLM001-財務計算用'!$A:$A,A11)=0,"未登入",SUMIFS('PLM001-財務計算用'!$P:$P,'PLM001-財務計算用'!$A:$A,A11)) -> 未登入 | K11: =SUMIFS('PLM002'!#REF!,'PLM002'!$F:$F,$A11) -> #REF! | M11: =VLOOKUP(A11,專案進度表!$B:$DT,18,FALSE) -> #N/A | N11: =IF(VLOOKUP(A11,'PLM014'!$B:$R,17,FALSE)=0,"",VLOOKUP(A11,'PLM014'!$B:$R,17,FALSE)) -> #N/A
A13: RD1
A14: 專案編號 | B14: 專案名稱 | D14: 專案負責人 | E14: 專案狀態 | F14: 預計起始日 | G14: 預計完成日 | H14: 實際開始日 | I14: 實際完成日 | J14: 預計設工時 | K14: 實際設計工時 | L14: 本週投入設工 | M14: 專案是否異常 | N14: 工況試煉送樣 | O14: 異常說明 | P14: 需要的協助 | Q14: 預計完成日
A15: D250802R1 | B15: =VLOOKUP(A15,專案進度表!B:DT,2,FALSE) -> 申請量桶量槽製作資格 | C15: =VLOOKUP(A15,專案進度表!$B:$DT,4,FALSE) -> 研一部 | D15: =VLOOKUP(A15,專案進度表!$B:$DT,5,FALSE) -> 何昆達 | E15: =VLOOKUP(A15,專案進度表!$B:$DT,6,FALSE) -> Active | F15: =VLOOKUP(A15,專案進度表!$B:$DT,7,FALSE) -> 45886.667 | G15: =VLOOKUP(A15,專案進度表!$B:$DT,8,FALSE) -> 46049.667 | H15: =IF(VLOOKUP(A15,專案進度表!$B:$DT,12,FALSE)=0,"",VLOOKUP(A15,專案進度表!$B:$DT,12,FALSE)) -> 45887 | I15: =IF(VLOOKUP(A15,專案進度表!$B:$DT,13,FALSE)=0,"",VLOOKUP(A15,專案進度表!$B:$DT,13,FALSE)) | J15: =IF(SUMIFS('PLM001-財務計算用'!$P:$P,'PLM001-財務計算用'!$A:$A,A15)=0,"未登入",SUMIFS('PLM001-財務計算用'!$P:$P,'PLM001-財務計算用'!$A:$A,A15)) -> 184 | K15: =SUMIFS('PLM002'!$K:$K,'PLM002'!$F:$F,$A15) -> 172.7 | L15: =IF(SUMIFS('PLM002'!$K:$K,'PLM002'!$F:$F,A15,'PLM002'!$J:$J,">="&$B$1,'PLM002'!$J:$J,"<="&$C$1)=0,"未投入",SUMIFS('PLM002'!$K:$K,'PLM002'!$F:$F,A15,'PLM002'!$J:$J,">="&$B$1,'PLM002'!$J:$J,"<="&$C$1)) -> 172.7 | M15: =VLOOKUP(A15,專案進度表!$B:$DT,18,FALSE) -> 專案即將異常 | N15: =IF(VLOOKUP(A15,'PLM014'!$B:$R,17,FALSE)=0,"",VLOOKUP(A15,'PLM014'!$B:$R,17,FALSE)) | O15: 1. 已取得電子天平校正報告 2. 電磁流量計校正9/26日完成，10/2日報告審查簽核完成。 3. 10/3日提供至標檢局文件覆核 10/17, 標檢局通知已經完成文件審核，待通知實地查核的時間，預定10/30進行。 10/31,標檢局31日已完成實地查核，預計兩周後發證。 11/13日已取得證書 4. 本周提交標準局標定文件，安排量筒標定日期 12/1, 今日申請量桶標定付款，安排12/8日標定 工研院校正安排於12/17~18日，預計12月份可完成量桶導入使用。 12/19, 工研院量筒校正已完成
A16: K240801R2 | B16: =VLOOKUP(A16,專案進度表!B:DT,2,FALSE) -> PCB濕製程用插入式壓力感測器 | C16: =VLOOKUP(A16,專案進度表!$B:$DT,4,FALSE) -> 研一部 | D16: =VLOOKUP(A16,專案進度表!$B:$DT,5,FALSE) -> 張良琪 | E16: =VLOOKUP(A16,專案進度表!$B:$DT,6,FALSE) -> Active | F16: =VLOOKUP(A16,專案進度表!$B:$DT,7,FALSE) -> 45641.667 | G16: =VLOOKUP(A16,專案進度表!$B:$DT,8,FALSE) -> 45807.667 | H16: =IF(VLOOKUP(A16,專案進度表!$B:$DT,12,FALSE)=0,"",VLOOKUP(A16,專案進度表!$B:$DT,12,FALSE)) -> 45524 | I16: =IF(VLOOKUP(A16,專案進度表!$B:$DT,13,FALSE)=0,"",VLOOKUP(A16,專案進度表!$B:$DT,13,FALSE)) | J16: =IF(SUMIFS('PLM001-財務計算用'!$P:$P,'PLM001-財務計算用'!$A:$A,A16)=0,"未登入",SUMIFS('PLM001-財務計算用'!$P:$P,'PLM001-財務計算用'!$A:$A,A16)) -> 1146 | K16: =SUMIFS('PLM002'!$K:$K,'PLM002'!$F:$F,$A16) -> 2762.3 | L16: =IF(SUMIFS('PLM002'!$K:$K,'PLM002'!$F:$F,A16,'PLM002'!$J:$J,">="&$B$1,'PLM002'!$J:$J,"<="&$C$1)=0,"未投入",SUMIFS('PLM002'!$K:$K,'PLM002'!$F:$F,A16,'PLM002'!$J:$J,">="&$B$1,'PLM002'!$J:$J,"<="&$C$1)) -> 2649.3 | M16: =VLOOKUP(A16,專案進度表!$B:$DT,18,FALSE) -> 專案延遲 237 天 | N16: =IF(VLOOKUP(A16,'PLM014'!$B:$R,17,FALSE)=0,"",VLOOKUP(A16,'PLM014'!$B:$R,17,FALSE)) -> 45709 | O16: 12/1, 200PCS結構已到上海，本週海運寄出，預計兩週到土城 11/20, 本週已準備6PCS樣品供上海展覽使用 本週拜訪永煜機械，為PCB製程末端電鍍設備製造商，壓力表材質可使用陶瓷+PVDF，目前使用表頭直徑2"，我司83mm安裝於過濾桶上空間不足。 12/19, 12/16工程試製會議完成,本周一會議決議修改文件及製程,生管開單生產50套安排於月底進行 | Q16: 預計9月份進行工程試製10月份技轉關案。 9/5,備料延至9/30，工程試製時間延後製10月份 外殼預計11/7日到200套，工程試製延至11月 供應商尺寸製作錯誤，延至12/5日到貨，工程試製延至12月份。
A17: M251201R1 | B17: =VLOOKUP(A17,專案進度表!B:DT,2,FALSE) -> 緊湊型渦街流量計導入專案 | C17: =VLOOKUP(A17,專案進度表!$B:$DT,4,FALSE) -> 研一部 | D17: =VLOOKUP(A17,專案進度表!$B:$DT,5,FALSE) -> 陳奕宏 | E17: =VLOOKUP(A17,專案進度表!$B:$DT,6,FALSE) -> Active | F17: =VLOOKUP(A17,專案進度表!$B:$DT,7,FALSE) -> 46005.667 | G17: =VLOOKUP(A17,專案進度表!$B:$DT,8,FALSE) -> 46079.667 | H17: =IF(VLOOKUP(A17,專案進度表!$B:$DT,12,FALSE)=0,"",VLOOKUP(A17,專案進度表!$B:$DT,12,FALSE)) | I17: =IF(VLOOKUP(A17,專案進度表!$B:$DT,13,FALSE)=0,"",VLOOKUP(A17,專案進度表!$B:$DT,13,FALSE)) | J17: =IF(SUMIFS('PLM001-財務計算用'!$P:$P,'PLM001-財務計算用'!$A:$A,A17)=0,"未登入",SUMIFS('PLM001-財務計算用'!$P:$P,'PLM001-財務計算用'!$A:$A,A17)) -> 436 | K17: =SUMIFS('PLM002'!$K:$K,'PLM002'!$F:$F,$A17) -> 1 | L17: =IF(SUMIFS('PLM002'!$K:$K,'PLM002'!$F:$F,A17,'PLM002'!$J:$J,">="&$B$1,'PLM002'!$J:$J,"<="&$C$1)=0,"未投入",SUMIFS('PLM002'!$K:$K,'PLM002'!$F:$F,A17,'PLM002'!$J:$J,">="&$B$1,'PLM002'!$J:$J,"<="&$C$1)) -> 1 | M17: =VLOOKUP(A17,專案進度表!$B:$DT,18,FALSE) -> 專案即將異常 | N17: =IF(VLOOKUP(A17,'PLM014'!$B:$R,17,FALSE)=0,"",VLOOKUP(A17,'PLM014'!$B:$R,17,FALSE)) -> 46062
A19: RD2
A20: 專案編號 | B20: 專案名稱 | D20: 專案負責人 | E20: 專案狀態 | F20: 預計起始日 | G20: 預計完成日 | H20: 實際開始日 | I20: 實際完成日 | J20: 預計設工時 | K20: 實際設計工時 | L20: 本週投入設工 | M20: 專案是否異常 | N20: 工況試煉送樣 | O20: 異常說明 | P20: 需要的協助 | Q20: 預計完成日
A21: D250101R1 | B21: =VLOOKUP(A21,專案進度表!B:DT,2,FALSE) -> AI冷卻系統數位通訊溫度偵測器 | C21: =VLOOKUP(A21,專案進度表!$B:$DT,4,FALSE) -> 研二部 | D21: =VLOOKUP(A21,專案進度表!$B:$DT,5,FALSE) -> 黃胤綸 | E21: =VLOOKUP(A21,專案進度表!$B:$DT,6,FALSE) -> Active | F21: =VLOOKUP(A21,專案進度表!$B:$DT,7,FALSE) -> 45669.667 | G21: =VLOOKUP(A21,專案進度表!$B:$DT,8,FALSE) -> 45776.667 | H21: =IF(VLOOKUP(A21,專案進度表!$B:$DT,12,FALSE)=0,"",VLOOKUP(A21,專案進度表!$B:$DT,12,FALSE)) -> 45670 | I21: =IF(VLOOKUP(A21,專案進度表!$B:$DT,13,FALSE)=0,"",VLOOKUP(A21,專案進度表!$B:$DT,13,FALSE)) | J21: =IF(SUMIFS('PLM001-財務計算用'!$P:$P,'PLM001-財務計算用'!$A:$A,A21)=0,"未登入",SUMIFS('PLM001-財務計算用'!$P:$P,'PLM001-財務計算用'!$A:$A,A21)) -> 795 | K21: =SUMIFS('PLM002'!$K:$K,'PLM002'!$F:$F,$A21) -> 1258 | L21: =IF(SUMIFS('PLM002'!$K:$K,'PLM002'!$F:$F,A21,'PLM002'!$J:$J,">="&$B$1,'PLM002'!$J:$J,"<="&$C$1)=0,"未投入",SUMIFS('PLM002'!$K:$K,'PLM002'!$F:$F,A21,'PLM002'!$J:$J,">="&$B$1,'PLM002'!$J:$J,"<="&$C$1)) -> 1258 | M21: =VLOOKUP(A21,專案進度表!$B:$DT,18,FALSE) -> 專案延遲 268 天 | N21: =IF(VLOOKUP(A21,'PLM014'!$B:$R,17,FALSE)=0,"",VLOOKUP(A21,'PLM014'!$B:$R,17,FALSE)) -> 45700 | O21: 1/19 1. GPX8具RS485功能治具, 使用WIKA恆溫水槽, 安排工程試製, 預計1月底召開行前會議. 2. GPX8-PT1000量產設備試俥, 設備器差與軟體整合已測試完成, SOP已完成, 本週試俥之前170 PCS不良品同時, 請電一派人來學習使用. | P21: GPX8成品校驗治具自動化已確認, 簽核後購買設備, 預計3週後開始組裝. | Q21: 工程試製預估1個月, 完成後再2週技轉。
A22: D250702R1 | B22: =VLOOKUP(A22,專案進度表!B:DT,2,FALSE) -> 2025年度-硬體模組化專案 | C22: =VLOOKUP(A22,專案進度表!$B:$DT,4,FALSE) -> 研二部 | D22: =VLOOKUP(A22,專案進度表!$B:$DT,5,FALSE) -> 黃胤綸 | E22: =VLOOKUP(A22,專案進度表!$B:$DT,6,FALSE) -> Active | F22: =VLOOKUP(A22,專案進度表!$B:$DT,7,FALSE) -> 45657.667 | G22: =VLOOKUP(A22,專案進度表!$B:$DT,8,FALSE) -> 46021.667 | H22: =IF(VLOOKUP(A22,專案進度表!$B:$DT,12,FALSE)=0,"",VLOOKUP(A22,專案進度表!$B:$DT,12,FALSE)) -> 45847 | I22: =IF(VLOOKUP(A22,專案進度表!$B:$DT,13,FALSE)=0,"",VLOOKUP(A22,專案進度表!$B:$DT,13,FALSE)) | J22: =IF(SUMIFS('PLM001-財務計算用'!$P:$P,'PLM001-財務計算用'!$A:$A,A22)=0,"未登入",SUMIFS('PLM001-財務計算用'!$P:$P,'PLM001-財務計算用'!$A:$A,A22)) -> 488 | K22: =SUMIFS('PLM002'!$K:$K,'PLM002'!$F:$F,$A22) -> 589.6 | L22: =IF(SUMIFS('PLM002'!$K:$K,'PLM002'!$F:$F,A22,'PLM002'!$J:$J,">="&$B$1,'PLM002'!$J:$J,"<="&$C$1)=0,"未投入",SUMIFS('PLM002'!$K:$K,'PLM002'!$F:$F,A22,'PLM002'!$J:$J,">="&$B$1,'PLM002'!$J:$J,"<="&$C$1)) -> 589.6 | M22: =VLOOKUP(A22,專案進度表!$B:$DT,18,FALSE) -> 專案延遲 23 天 | N22: =IF(VLOOKUP(A22,'PLM014'!$B:$R,17,FALSE)=0,"",VLOOKUP(A22,'PLM014'!$B:$R,17,FALSE))
A23: M250201C1 | B23: =VLOOKUP(A23,專案進度表!B:DT,2,FALSE) -> 工業爆炸環境防爆型音叉感測器 | C23: =VLOOKUP(A23,專案進度表!$B:$DT,4,FALSE) -> 研二部 | D23: =VLOOKUP(A23,專案進度表!$B:$DT,5,FALSE) -> 黃胤綸 | E23: =VLOOKUP(A23,專案進度表!$B:$DT,6,FALSE) -> Active | F23: =VLOOKUP(A23,專案進度表!$B:$DT,7,FALSE) -> 45713.667 | G23: =VLOOKUP(A23,專案進度表!$B:$DT,8,FALSE) -> 45922.667 | H23: =IF(VLOOKUP(A23,專案進度表!$B:$DT,12,FALSE)=0,"",VLOOKUP(A23,專案進度表!$B:$DT,12,FALSE)) -> 45713 | I23: =IF(VLOOKUP(A23,專案進度表!$B:$DT,13,FALSE)=0,"",VLOOKUP(A23,專案進度表!$B:$DT,13,FALSE)) | J23: =IF(SUMIFS('PLM001-財務計算用'!$P:$P,'PLM001-財務計算用'!$A:$A,A23)=0,"未登入",SUMIFS('PLM001-財務計算用'!$P:$P,'PLM001-財務計算用'!$A:$A,A23)) -> 708 | K23: =SUMIFS('PLM002'!$K:$K,'PLM002'!$F:$F,$A23) -> 1030 | L23: =IF(SUMIFS('PLM002'!$K:$K,'PLM002'!$F:$F,A23,'PLM002'!$J:$J,">="&$B$1,'PLM002'!$J:$J,"<="&$C$1)=0,"未投入",SUMIFS('PLM002'!$K:$K,'PLM002'!$F:$F,A23,'PLM002'!$J:$J,">="&$B$1,'PLM002'!$J:$J,"<="&$C$1)) -> 1030 | M23: =VLOOKUP(A23,專案進度表!$B:$DT,18,FALSE) -> 專案延遲 122 天 | N23: =IF(VLOOKUP(A23,'PLM014'!$B:$R,17,FALSE)=0,"",VLOOKUP(A23,'PLM014'!$B:$R,17,FALSE)) | O23: 1/19 1. 溫昇測試11/20完成. 2. 高溫220度C/高壓200bar測試完成. 3. 老化測試後IP67 1/16測試PASS, 剩水壓與非傳測試, 預計1/23前完成. | Q23: 預計2026/2月底取證
A24: M251001R1 | B24: =VLOOKUP(A24,專案進度表!B:DT,2,FALSE) -> SDX光電開關微型化設計 | C24: =VLOOKUP(A24,專案進度表!$B:$DT,4,FALSE) -> 研二部 | D24: =VLOOKUP(A24,專案進度表!$B:$DT,5,FALSE) -> 彭志豪 | E24: =VLOOKUP(A24,專案進度表!$B:$DT,6,FALSE) -> Active | F24: =VLOOKUP(A24,專案進度表!$B:$DT,7,FALSE) -> 45966.667 | G24: =VLOOKUP(A24,專案進度表!$B:$DT,8,FALSE) -> 46128.667 | H24: =IF(VLOOKUP(A24,專案進度表!$B:$DT,12,FALSE)=0,"",VLOOKUP(A24,專案進度表!$B:$DT,12,FALSE)) -> 45950 | I24: =IF(VLOOKUP(A24,專案進度表!$B:$DT,13,FALSE)=0,"",VLOOKUP(A24,專案進度表!$B:$DT,13,FALSE)) | J24: =IF(SUMIFS('PLM001-財務計算用'!$P:$P,'PLM001-財務計算用'!$A:$A,A24)=0,"未登入",SUMIFS('PLM001-財務計算用'!$P:$P,'PLM001-財務計算用'!$A:$A,A24)) -> 419 | K24: =SUMIFS('PLM002'!$K:$K,'PLM002'!$F:$F,$A24) -> 794 | L24: =IF(SUMIFS('PLM002'!$K:$K,'PLM002'!$F:$F,A24,'PLM002'!$J:$J,">="&$B$1,'PLM002'!$J:$J,"<="&$C$1)=0,"未投入",SUMIFS('PLM002'!$K:$K,'PLM002'!$F:$F,A24,'PLM002'!$J:$J,">="&$B$1,'PLM002'!$J:$J,"<="&$C$1)) -> 794 | M24: =VLOOKUP(A24,專案進度表!$B:$DT,18,FALSE) | N24: =IF(VLOOKUP(A24,'PLM014'!$B:$R,17,FALSE)=0,"",VLOOKUP(A24,'PLM014'!$B:$R,17,FALSE)) -> 46065 | O24: 1/19 1. 開模(太陽片)預計2026/1/23回廠. 2. 電路已驗證完成, 會再改一版與新增PNP型. 3. 本週試低壓射出模具並試裝成品測功能. | Q24: 樣品預計2026/2/12提供
A26: RD3
A27: 專案編號 | B27: 專案名稱 | D27: 專案負責人 | E27: 專案狀態 | F27: 預計起始日 | G27: 預計完成日 | H27: 實際開始日 | I27: 實際完成日 | J27: 預計設工時 | K27: 實際設計工時 | L27: 本週投入設工 | M27: 專案是否異常 | N27: 工況試煉送樣 | O27: 異常說明 | P27: 需要的協助 | Q27: 預計完成日
A28: M240704R1 | B28: =VLOOKUP(A28,專案進度表!B:DT,2,FALSE) -> 一體式夾管超音波流量計(DN25)[RD4] | C28: =VLOOKUP(A28,專案進度表!$B:$DT,4,FALSE) -> 研三部 | D28: =VLOOKUP(A28,專案進度表!$B:$DT,5,FALSE) -> 陳俊儒 | E28: =VLOOKUP(A28,專案進度表!$B:$DT,6,FALSE) -> Active | F28: =VLOOKUP(A28,專案進度表!$B:$DT,7,FALSE) -> 45536.667 | G28: =VLOOKUP(A28,專案進度表!$B:$DT,8,FALSE) -> 45755.667 | H28: =IF(VLOOKUP(A28,專案進度表!$B:$DT,12,FALSE)=0,"",VLOOKUP(A28,專案進度表!$B:$DT,12,FALSE)) -> 45537 | I28: =IF(VLOOKUP(A28,專案進度表!$B:$DT,13,FALSE)=0,"",VLOOKUP(A28,專案進度表!$B:$DT,13,FALSE)) | J28: =IF(SUMIFS('PLM001-財務計算用'!$P:$P,'PLM001-財務計算用'!$A:$A,A28)=0,"未登入",SUMIFS('PLM001-財務計算用'!$P:$P,'PLM001-財務計算用'!$A:$A,A28)) -> 1896 | K28: =SUMIFS('PLM002'!$K:$K,'PLM002'!$F:$F,$A28) -> 7306.6 | L28: =IF(SUMIFS('PLM002'!$K:$K,'PLM002'!$F:$F,A28,'PLM002'!$J:$J,">="&$B$1,'PLM002'!$J:$J,"<="&$C$1)=0,"未投入",SUMIFS('PLM002'!$K:$K,'PLM002'!$F:$F,A28,'PLM002'!$J:$J,">="&$B$1,'PLM002'!$J:$J,"<="&$C$1)) -> 5536.1 | M28: =VLOOKUP(A28,專案進度表!$B:$DT,18,FALSE) | N28: =IF(VLOOKUP(A28,'PLM014'!$B:$R,17,FALSE)=0,"",VLOOKUP(A28,'PLM014'!$B:$R,17,FALSE)) -> 45695 | O28: 10/20 目前進度：探頭PEI + 壓電壓貼合後的訊號量測作業。 10/28 目前進度：背膠層灌膠後等待乾燥。目前確認損壞的樣品為4/60 = 7% 11/14 已完成試作，目前正在完善文件及測試結果統計分析。 11/22 資料已整理完成，待台大做結案報告(日期待定。) | P28: 11/18公司確認時間，讓台大做結案報告。 | Q28: 45991
A29: M250301R1 | B29: =VLOOKUP(A29,專案進度表!B:DT,2,FALSE) -> 軌道型顯示器夾管式超音波流量計 | C29: =VLOOKUP(A29,專案進度表!$B:$DT,4,FALSE) -> 研三部 | D29: =VLOOKUP(A29,專案進度表!$B:$DT,5,FALSE) -> 陳俊儒 | E29: =VLOOKUP(A29,專案進度表!$B:$DT,6,FALSE) -> Active | F29: =VLOOKUP(A29,專案進度表!$B:$DT,7,FALSE) -> 45747.667 | G29: =VLOOKUP(A29,專案進度表!$B:$DT,8,FALSE) -> 46008.667 | H29: =IF(VLOOKUP(A29,專案進度表!$B:$DT,12,FALSE)=0,"",VLOOKUP(A29,專案進度表!$B:$DT,12,FALSE)) -> 45748 | I29: =IF(VLOOKUP(A29,專案進度表!$B:$DT,13,FALSE)=0,"",VLOOKUP(A29,專案進度表!$B:$DT,13,FALSE)) | J29: =IF(SUMIFS('PLM001-財務計算用'!$P:$P,'PLM001-財務計算用'!$A:$A,A29)=0,"未登入",SUMIFS('PLM001-財務計算用'!$P:$P,'PLM001-財務計算用'!$A:$A,A29)) -> 722 | K29: =SUMIFS('PLM002'!$K:$K,'PLM002'!$F:$F,$A29) -> 1172.6 | L29: =IF(SUMIFS('PLM002'!$K:$K,'PLM002'!$F:$F,A29,'PLM002'!$J:$J,">="&$B$1,'PLM002'!$J:$J,"<="&$C$1)=0,"未投入",SUMIFS('PLM002'!$K:$K,'PLM002'!$F:$F,A29,'PLM002'!$J:$J,">="&$B$1,'PLM002'!$J:$J,"<="&$C$1)) -> 1172.6 | M29: =VLOOKUP(A29,專案進度表!$B:$DT,18,FALSE) -> 專案延遲 36 天 | N29: =IF(VLOOKUP(A29,'PLM014'!$B:$R,17,FALSE)=0,"",VLOOKUP(A29,'PLM014'!$B:$R,17,FALSE)) -> 45916 | O29: 9/26 召開規格變更會議，確認EUT-POWER 2KV接地也要通過。環境溫度標示，若在常溫，並且水溫80℃時可正常工作，型錄的環境溫度維持60℃的標示。 10/20 已確定高溫80℃的水溫，可以正常工作。 10/28 預計11/6投入工程試製。50PCS 11/14 外殼11/17到貨，預計11/18進產線。 11/14 DN15量測訊號問題，目前尋求探頭更改型式的方式嘗試解決。 | P29: 1.EPU2生產專用測場重新建置。 2.探頭組裝防水膠體填充耗時問題處理 | Q29: 46021
A30: D250803R1 | B30: =VLOOKUP(A30,專案進度表!B:DT,2,FALSE) -> 台大超音波探頭貼合技術技轉案 | C30: =VLOOKUP(A30,專案進度表!$B:$DT,4,FALSE) -> 研三部 | D30: =VLOOKUP(A30,專案進度表!$B:$DT,5,FALSE) -> 陳俊儒 | E30: =VLOOKUP(A30,專案進度表!$B:$DT,6,FALSE) -> Closed | F30: =VLOOKUP(A30,專案進度表!$B:$DT,7,FALSE) -> 45900.667 | G30: =VLOOKUP(A30,專案進度表!$B:$DT,8,FALSE) -> 45988.667 | H30: =IF(VLOOKUP(A30,專案進度表!$B:$DT,12,FALSE)=0,"",VLOOKUP(A30,專案進度表!$B:$DT,12,FALSE)) -> 45939 | I30: =IF(VLOOKUP(A30,專案進度表!$B:$DT,13,FALSE)=0,"",VLOOKUP(A30,專案進度表!$B:$DT,13,FALSE)) -> 46030 | J30: =IF(SUMIFS('PLM001-財務計算用'!$P:$P,'PLM001-財務計算用'!$A:$A,A30)=0,"未登入",SUMIFS('PLM001-財務計算用'!$P:$P,'PLM001-財務計算用'!$A:$A,A30)) -> 未登入 | K30: =SUMIFS('PLM002'!$K:$K,'PLM002'!$F:$F,$A30) -> 253.5 | L30: =IF(SUMIFS('PLM002'!$K:$K,'PLM002'!$F:$F,A30,'PLM002'!$J:$J,">="&$B$1,'PLM002'!$J:$J,"<="&$C$1)=0,"未投入",SUMIFS('PLM002'!$K:$K,'PLM002'!$F:$F,A30,'PLM002'!$J:$J,">="&$B$1,'PLM002'!$J:$J,"<="&$C$1)) -> 253.5 | M30: =VLOOKUP(A30,專案進度表!$B:$DT,18,FALSE) | N30: =IF(VLOOKUP(A30,'PLM014'!$B:$R,17,FALSE)=0,"",VLOOKUP(A30,'PLM014'!$B:$R,17,FALSE)) | O30: 9/26 電路已可正常工作，本週進行實際訊號測試。 10/20 電路測試正常，但EFT 3KV異常處理中。 10/28 EFT 3KV時電源12V異常，尚未查明。 11/4 目前EFT 測試已改善到畫面黑白對調，但產品運作正常的情況，預計本週可以處理完成。 11/14 已送進DVT-QA 11/25 準備Relayout 作業。 | P30: 目前人力不足Debug速度較慢 | Q30: 46021
A32: 產品開發
A33: 專案編號 | B33: 專案名稱 | D33: 專案負責人 | E33: 專案狀態 | F33: 預計起始日 | G33: 預計完成日 | H33: 實際開始日 | I33: 實際完成日 | J33: 預計設工時 | K33: 實際設計工時 | L33: 本週投入設工 | M33: 專案是否異常 | N33: 工況試煉送樣 | O33: 異常說明 | P33: 需要的協助 | Q33: 預計完成日
A34: D240902R1 | B34: =VLOOKUP(A34,專案進度表!B:DT,2,FALSE) -> EPH結構改善與提升生產良率 | C34: =VLOOKUP(A34,專案進度表!$B:$DT,4,FALSE) -> 產品開發 | D34: =VLOOKUP(A34,專案進度表!$B:$DT,5,FALSE) -> 王瀚霆 | E34: =VLOOKUP(A34,專案進度表!$B:$DT,6,FALSE) -> Active | F34: =VLOOKUP(A34,專案進度表!$B:$DT,7,FALSE) -> 45557.667 | G34: =VLOOKUP(A34,專案進度表!$B:$DT,8,FALSE) -> 45620.667 | H34: =IF(VLOOKUP(A34,專案進度表!$B:$DT,12,FALSE)=0,"",VLOOKUP(A34,專案進度表!$B:$DT,12,FALSE)) -> 45558 | I34: =IF(VLOOKUP(A34,專案進度表!$B:$DT,13,FALSE)=0,"",VLOOKUP(A34,專案進度表!$B:$DT,13,FALSE)) | J34: =IF(SUMIFS('PLM001-財務計算用'!$P:$P,'PLM001-財務計算用'!$A:$A,A34)=0,"未登入",SUMIFS('PLM001-財務計算用'!$P:$P,'PLM001-財務計算用'!$A:$A,A34)) -> 220 | K34: =SUMIFS('PLM002'!$K:$K,'PLM002'!$F:$F,$A34) -> 936.5 | L34: =IF(SUMIFS('PLM002'!$K:$K,'PLM002'!$F:$F,A34,'PLM002'!$J:$J,">="&$B$1,'PLM002'!$J:$J,"<="&$C$1)=0,"未投入",SUMIFS('PLM002'!$K:$K,'PLM002'!$F:$F,A34,'PLM002'!$J:$J,">="&$B$1,'PLM002'!$J:$J,"<="&$C$1)) -> 683.5 | M34: =VLOOKUP(A34,專案進度表!$B:$DT,18,FALSE) -> 專案延遲 424 天 | N34: =IF(VLOOKUP(A34,'PLM014'!$B:$R,17,FALSE)=0,"",VLOOKUP(A34,'PLM014'!$B:$R,17,FALSE)) | O34: DN13改善: 多孔式噴嘴(縮小入水孔高度)、氣密墊圈 DN20改善: 多孔式噴嘴(8孔改7孔入水孔、縮小入水孔距離)、氣密墊圈 DN25改善: 多孔式噴嘴(更換為舊DN20)、氣密墊圈、葉片(更換為舊DN20) DN40改善: 多孔式噴嘴(11孔改10孔入水孔、入水孔加大)、支撐環、氣密墊圈 | Q34: DN13~DN40 相關模具、已修改完成。 圖面修改完成(7/31) BOM表變更完成(7/31)
A35: K250501R1 | B35: =VLOOKUP(A35,專案進度表!B:DT,2,FALSE) -> C級奧多曼電子水表先期研究 | C35: =VLOOKUP(A35,專案進度表!$B:$DT,4,FALSE) -> 產品開發 | D35: =VLOOKUP(A35,專案進度表!$B:$DT,5,FALSE) -> 鄭貫中 | E35: =VLOOKUP(A35,專案進度表!$B:$DT,6,FALSE) -> Active | F35: =VLOOKUP(A35,專案進度表!$B:$DT,7,FALSE) -> 45816.667 | G35: =VLOOKUP(A35,專案進度表!$B:$DT,8,FALSE) -> 45883.667 | H35: =IF(VLOOKUP(A35,專案進度表!$B:$DT,12,FALSE)=0,"",VLOOKUP(A35,專案進度表!$B:$DT,12,FALSE)) -> 45811 | I35: =IF(VLOOKUP(A35,專案進度表!$B:$DT,13,FALSE)=0,"",VLOOKUP(A35,專案進度表!$B:$DT,13,FALSE)) | J35: =IF(SUMIFS('PLM001-財務計算用'!$P:$P,'PLM001-財務計算用'!$A:$A,A35)=0,"未登入",SUMIFS('PLM001-財務計算用'!$P:$P,'PLM001-財務計算用'!$A:$A,A35)) -> 462 | K35: =SUMIFS('PLM002'!$K:$K,'PLM002'!$F:$F,$A35) -> 840.5 | L35: =IF(SUMIFS('PLM002'!$K:$K,'PLM002'!$F:$F,A35,'PLM002'!$J:$J,">="&$B$1,'PLM002'!$J:$J,"<="&$C$1)=0,"未投入",SUMIFS('PLM002'!$K:$K,'PLM002'!$F:$F,A35,'PLM002'!$J:$J,">="&$B$1,'PLM002'!$J:$J,"<="&$C$1)) -> 840.5 | M35: =VLOOKUP(A35,專案進度表!$B:$DT,18,FALSE) -> 專案延遲 161 天 | N35: =IF(VLOOKUP(A35,'PLM014'!$B:$R,17,FALSE)=0,"",VLOOKUP(A35,'PLM014'!$B:$R,17,FALSE)) | O35: 結案報告撰寫中
A36: K250501R2 | B36: =VLOOKUP(A36,專案進度表!B:DT,2,FALSE) -> C級奧多曼電子水量計 | C36: =VLOOKUP(A36,專案進度表!$B:$DT,4,FALSE) -> 產品開發 | D36: =VLOOKUP(A36,專案進度表!$B:$DT,5,FALSE) -> 鄭貫中 | E36: =VLOOKUP(A36,專案進度表!$B:$DT,6,FALSE) -> Active | F36: =VLOOKUP(A36,專案進度表!$B:$DT,7,FALSE) -> 46001.667 | G36: =VLOOKUP(A36,專案進度表!$B:$DT,8,FALSE) -> 46324.667 | H36: =IF(VLOOKUP(A36,專案進度表!$B:$DT,12,FALSE)=0,"",VLOOKUP(A36,專案進度表!$B:$DT,12,FALSE)) -> 46013 | I36: =IF(VLOOKUP(A36,專案進度表!$B:$DT,13,FALSE)=0,"",VLOOKUP(A36,專案進度表!$B:$DT,13,FALSE)) | J36: =IF(SUMIFS('PLM001-財務計算用'!$P:$P,'PLM001-財務計算用'!$A:$A,A36)=0,"未登入",SUMIFS('PLM001-財務計算用'!$P:$P,'PLM001-財務計算用'!$A:$A,A36)) -> 840 | K36: =SUMIFS('PLM002'!$K:$K,'PLM002'!$F:$F,$A36) -> 258.5 | L36: =IF(SUMIFS('PLM002'!$K:$K,'PLM002'!$F:$F,A36,'PLM002'!$J:$J,">="&$B$1,'PLM002'!$J:$J,"<="&$C$1)=0,"未投入",SUMIFS('PLM002'!$K:$K,'PLM002'!$F:$F,A36,'PLM002'!$J:$J,">="&$B$1,'PLM002'!$J:$J,"<="&$C$1)) -> 258.5 | M36: =VLOOKUP(A36,專案進度表!$B:$DT,18,FALSE) | N36: =IF(VLOOKUP(A36,'PLM014'!$B:$R,17,FALSE)=0,"",VLOOKUP(A36,'PLM014'!$B:$R,17,FALSE))
A37: K251001R1 | B37: =VLOOKUP(A37,專案進度表!B:DT,2,FALSE) -> EPH水量計型式認證技術規範CNPA49第4版結構驗證與改善 | C37: =VLOOKUP(A37,專案進度表!$B:$DT,4,FALSE) -> 產品開發 | D37: =VLOOKUP(A37,專案進度表!$B:$DT,5,FALSE) -> 王瀚霆 | E37: =VLOOKUP(A37,專案進度表!$B:$DT,6,FALSE) -> Active | F37: =VLOOKUP(A37,專案進度表!$B:$DT,7,FALSE) -> 45985.667 | G37: =VLOOKUP(A37,專案進度表!$B:$DT,8,FALSE) -> 46202.667 | H37: =IF(VLOOKUP(A37,專案進度表!$B:$DT,12,FALSE)=0,"",VLOOKUP(A37,專案進度表!$B:$DT,12,FALSE)) -> 46036 | I37: =IF(VLOOKUP(A37,專案進度表!$B:$DT,13,FALSE)=0,"",VLOOKUP(A37,專案進度表!$B:$DT,13,FALSE)) | J37: =IF(SUMIFS('PLM001-財務計算用'!$P:$P,'PLM001-財務計算用'!$A:$A,A37)=0,"未登入",SUMIFS('PLM001-財務計算用'!$P:$P,'PLM001-財務計算用'!$A:$A,A37)) -> 1011 | K37: =SUMIFS('PLM002'!$K:$K,'PLM002'!$F:$F,$A37) -> 24.5 | L37: =IF(SUMIFS('PLM002'!$K:$K,'PLM002'!$F:$F,A37,'PLM002'!$J:$J,">="&$B$1,'PLM002'!$J:$J,"<="&$C$1)=0,"未投入",SUMIFS('PLM002'!$K:$K,'PLM002'!$F:$F,A37,'PLM002'!$J:$J,">="&$B$1,'PLM002'!$J:$J,"<="&$C$1)) -> 24.5 | M37: =VLOOKUP(A37,專案進度表!$B:$DT,18,FALSE) | N37: =IF(VLOOKUP(A37,'PLM014'!$B:$R,17,FALSE)=0,"",VLOOKUP(A37,'PLM014'!$B:$R,17,FALSE))
A38: M240804R1 | B38: =VLOOKUP(A38,專案進度表!B:DT,2,FALSE) -> PVD二口二位閥展型(DN15、DN20) | C38: =VLOOKUP(A38,專案進度表!$B:$DT,4,FALSE) -> 產品開發 | D38: =VLOOKUP(A38,專案進度表!$B:$DT,5,FALSE) -> 葉宏政 | E38: =VLOOKUP(A38,專案進度表!$B:$DT,6,FALSE) -> Active | F38: =VLOOKUP(A38,專案進度表!$B:$DT,7,FALSE) -> 45529.667 | G38: =VLOOKUP(A38,專案進度表!$B:$DT,8,FALSE) -> 45896.667 | H38: =IF(VLOOKUP(A38,專案進度表!$B:$DT,12,FALSE)=0,"",VLOOKUP(A38,專案進度表!$B:$DT,12,FALSE)) -> 45531 | I38: =IF(VLOOKUP(A38,專案進度表!$B:$DT,13,FALSE)=0,"",VLOOKUP(A38,專案進度表!$B:$DT,13,FALSE)) | J38: =IF(SUMIFS('PLM001-財務計算用'!$P:$P,'PLM001-財務計算用'!$A:$A,A38)=0,"未登入",SUMIFS('PLM001-財務計算用'!$P:$P,'PLM001-財務計算用'!$A:$A,A38)) -> 532 | K38: =SUMIFS('PLM002'!$K:$K,'PLM002'!$F:$F,$A38) -> 1318.5 | L38: =IF(SUMIFS('PLM002'!$K:$K,'PLM002'!$F:$F,A38,'PLM002'!$J:$J,">="&$B$1,'PLM002'!$J:$J,"<="&$C$1)=0,"未投入",SUMIFS('PLM002'!$K:$K,'PLM002'!$F:$F,A38,'PLM002'!$J:$J,">="&$B$1,'PLM002'!$J:$J,"<="&$C$1)) -> 745.5 | M38: =VLOOKUP(A38,專案進度表!$B:$DT,18,FALSE) -> 專案延遲 148 天 | N38: =IF(VLOOKUP(A38,'PLM014'!$B:$R,17,FALSE)=0,"",VLOOKUP(A38,'PLM014'!$B:$R,17,FALSE)) -> 45841
A40: FAE
A41: 專案編號 | B41: 專案名稱 | D41: 專案負責人 | E41: 專案狀態 | F41: 預計起始日 | G41: 預計完成日 | H41: 實際開始日 | I41: 實際完成日 | J41: 預計設工時 | K41: 實際設計工時 | L41: 本週投入設工 | M41: 專案是否異常 | N41: 工況試煉送樣 | O41: 異常說明 | P41: 需要的協助 | Q41: 預計完成日
A42: K240801C1 | B42: =VLOOKUP(A42,專案進度表!B:DT,2,FALSE) -> TS認證查核點-設備監控保護裝置(防爆燈拉繩開關125VDC) | C42: =VLOOKUP(A42,專案進度表!$B:$DT,4,FALSE) -> FAE | D42: =VLOOKUP(A42,專案進度表!$B:$DT,5,FALSE) -> 楊瑞洋 | E42: =VLOOKUP(A42,專案進度表!$B:$DT,6,FALSE) -> Active | F42: =VLOOKUP(A42,專案進度表!$B:$DT,7,FALSE) -> 45526.667 | G42: =VLOOKUP(A42,專案進度表!$B:$DT,8,FALSE) -> 46111.667 | H42: =IF(VLOOKUP(A42,專案進度表!$B:$DT,12,FALSE)=0,"",VLOOKUP(A42,專案進度表!$B:$DT,12,FALSE)) -> 45533 | I42: =IF(VLOOKUP(A42,專案進度表!$B:$DT,13,FALSE)=0,"",VLOOKUP(A42,專案進度表!$B:$DT,13,FALSE)) | J42: =IF(SUMIFS('PLM001-財務計算用'!$P:$P,'PLM001-財務計算用'!$A:$A,A42)=0,"未登入",SUMIFS('PLM001-財務計算用'!$P:$P,'PLM001-財務計算用'!$A:$A,A42)) -> 37 | K42: =SUMIFS('PLM002'!$K:$K,'PLM002'!$F:$F,$A42) -> 0 | L42: =IF(SUMIFS('PLM002'!$K:$K,'PLM002'!$F:$F,A42,'PLM002'!$J:$J,">="&$B$1,'PLM002'!$J:$J,"<="&$C$1)=0,"未投入",SUMIFS('PLM002'!$K:$K,'PLM002'!$F:$F,A42,'PLM002'!$J:$J,">="&$B$1,'PLM002'!$J:$J,"<="&$C$1)) -> 未投入 | M42: =VLOOKUP(A42,專案進度表!$B:$DT,18,FALSE) | N42: =IF(VLOOKUP(A42,'PLM014'!$B:$R,17,FALSE)=0,"",VLOOKUP(A42,'PLM014'!$B:$R,17,FALSE))
A44: 上海
A45: 專案編號 | B45: 專案名稱 | D45: 專案負責人 | E45: 專案狀態 | F45: 預計起始日 | G45: 預計完成日 | H45: 實際開始日 | I45: 實際完成日 | J45: 預計設工時 | K45: 實際設計工時 | L45: 本週投入設工 | M45: 專案是否異常 | N45: 工況試煉送樣 | O45: 異常說明 | P45: 需要的協助 | Q45: 預計完成日
A46: D250301R1 | B46: =VLOOKUP(A46,專案進度表!B:DT,2,FALSE) -> EPD電磁流量計技转 | C46: =VLOOKUP(A46,專案進度表!$B:$DT,4,FALSE) -> 研发一部 | D46: =VLOOKUP(A46,專案進度表!$B:$DT,5,FALSE) -> 汪佳凯 | E46: =VLOOKUP(A46,專案進度表!$B:$DT,6,FALSE) -> Active | F46: =VLOOKUP(A46,專案進度表!$B:$DT,7,FALSE) -> 45872.667 | G46: =VLOOKUP(A46,專案進度表!$B:$DT,8,FALSE) -> 46147.667 | H46: =IF(VLOOKUP(A46,專案進度表!$B:$DT,12,FALSE)=0,"",VLOOKUP(A46,專案進度表!$B:$DT,12,FALSE)) -> 45873 | I46: =IF(VLOOKUP(A46,專案進度表!$B:$DT,13,FALSE)=0,"",VLOOKUP(A46,專案進度表!$B:$DT,13,FALSE)) | J46: =IF(SUMIFS('PLM001-財務計算用'!$P:$P,'PLM001-財務計算用'!$A:$A,A46)=0,"未登入",SUMIFS('PLM001-財務計算用'!$P:$P,'PLM001-財務計算用'!$A:$A,A46)) -> 779 | K46: =SUMIFS('PLM002'!$K:$K,'PLM002'!$F:$F,$A46) -> 0 | L46: =IF(SUMIFS('PLM002'!$K:$K,'PLM002'!$F:$F,A46,'PLM002'!$J:$J,">="&$B$1,'PLM002'!$J:$J,"<="&$C$1)=0,"未投入",SUMIFS('PLM002'!$K:$K,'PLM002'!$F:$F,A46,'PLM002'!$J:$J,">="&$B$1,'PLM002'!$J:$J,"<="&$C$1)) -> 未投入 | M46: =VLOOKUP(A46,專案進度表!$B:$DT,18,FALSE) | N46: =IF(VLOOKUP(A46,'PLM014'!$B:$R,17,FALSE)=0,"",VLOOKUP(A46,'PLM014'!$B:$R,17,FALSE))
A47: D250701R1 | B47: =VLOOKUP(A47,專案進度表!B:DT,2,FALSE) -> EGX5标准型技转 | C47: =VLOOKUP(A47,專案進度表!$B:$DT,4,FALSE) -> 研发一部 | D47: =VLOOKUP(A47,專案進度表!$B:$DT,5,FALSE) -> 汪佳凯 | E47: =VLOOKUP(A47,專案進度表!$B:$DT,6,FALSE) -> Active | F47: =VLOOKUP(A47,專案進度表!$B:$DT,7,FALSE) -> 45872.667 | G47: =VLOOKUP(A47,專案進度表!$B:$DT,8,FALSE) -> 46076.667 | H47: =IF(VLOOKUP(A47,專案進度表!$B:$DT,12,FALSE)=0,"",VLOOKUP(A47,專案進度表!$B:$DT,12,FALSE)) -> 45873 | I47: =IF(VLOOKUP(A47,專案進度表!$B:$DT,13,FALSE)=0,"",VLOOKUP(A47,專案進度表!$B:$DT,13,FALSE)) | J47: =IF(SUMIFS('PLM001-財務計算用'!$P:$P,'PLM001-財務計算用'!$A:$A,A47)=0,"未登入",SUMIFS('PLM001-財務計算用'!$P:$P,'PLM001-財務計算用'!$A:$A,A47)) -> 839 | K47: =SUMIFS('PLM002'!$K:$K,'PLM002'!$F:$F,$A47) -> 0 | L47: =IF(SUMIFS('PLM002'!$K:$K,'PLM002'!$F:$F,A47,'PLM002'!$J:$J,">="&$B$1,'PLM002'!$J:$J,"<="&$C$1)=0,"未投入",SUMIFS('PLM002'!$K:$K,'PLM002'!$F:$F,A47,'PLM002'!$J:$J,">="&$B$1,'PLM002'!$J:$J,"<="&$C$1)) -> 未投入 | M47: =VLOOKUP(A47,專案進度表!$B:$DT,18,FALSE) | N47: =IF(VLOOKUP(A47,'PLM014'!$B:$R,17,FALSE)=0,"",VLOOKUP(A47,'PLM014'!$B:$R,17,FALSE))
...

Sheet 專案進度表
B1: 專案總進度表(RD/FAE/上海)
P2: 今天 | Q2: =TODAY() -> 46044
Y3: 研發一處 | AI3: 技術中心 | AS3: 研一部 | BC3: 研二部 | BK3: 研三部 | BS3: 產品開發 | BY3: 離職人員 | CW3: QA | DE3: 行銷 | DI3: FAE | DM3: 上海 | DQ3: 生管 | DS3: 自動化
A4: 專案類別 | B4: 專案編號 | C4: 專案名稱 | D4: 專案名稱 | E4: 部門名稱 | F4: 專案負責人 | G4: 專案狀態 | H4: 預計起始日 | I4: 預計完成日 | J4: 預計專案工期 | K4: 專案(75%) 日期 | L4: 專案(95%) 日期 | M4: 實際開始日 | N4: 實際完成日 | O4: 實際專案工期 | P4: 工期計算用 | Q4: 實際專案工期 | R4: 專案總進度 | S4: 專案是否 異常 | U4: 總設計工時 (hr) | W4: 總工(含其它單位) (hr) | Y4: 許慧芝 | AA4: 林逸舒 | AC4: 王淑瑤 | AE4: 賴慶樺 | AG4: 陳威諭 | AI4: 劉子明 | AK4: 蕭金椿 | AM4: 張文魁 | AO4: 張政崙 | AQ4: 李奕澔 | AS4: 張良琪 | AU4: 何昆達 | AW4: 鄭珅易 | AY4: 陳奕宏 | BA4: 劉益瑋 | BC4: 黃胤綸 | BE4: 莊廉琯 | BG4: 彭志豪 | BI4: 李騏敬 | BK4: 陳俊儒 | BM4: 魏暉恩 | BO4: 蘇哲弘 | BQ4: 許博元 | BS4: 王瀚霆 | BU4: 葉宏政 | BW4: 鄭貫中 | BY4: 陳冠銘 | CA4: 許凱崴 | CC4: 陳子揚 | CE4: 楊浩德 | CG4: 黃价利 | CI4: 黎育誠 | CK4: 簡振芳 | CM4: 江俊毅 | CO4: 丁智軒 | CQ4: 王俊博 | CS4: 洪子芸 | CU4: 蔣永華 | CW4: 王琇眉 | CY4: 余承翰 | DA4: 陳威宏 | DC4: 朱哲演 | DE4: 吳奎雍 | DG4: 吳志嘉 | DI4: 林宏銘 | DK4: 楊瑞洋 | DM4: 郑仁春 | DO4: 汪佳凯 | DQ4: 周家儀 | DS4: 王志文 | DU4: 郭景成 | DW4: 陳威瑜 | DY4: 羅友彥 | EA4: 李育儒 | EC4: 蘇漢城
U5: 預計 | V5: 實際 | W5: 預計 | X5: 實際 | Y5: 預計 | Z5: 實際 | AA5: 預計 | AB5: 實際 | AC5: 預計 | AD5: 實際 | AE5: 預計 | AF5: 實際 | AG5: 預計 | AH5: 實際 | AI5: 預計 | AJ5: 實際 | AK5: 預計 | AL5: 實際 | AM5: 預計 | AN5: 實際 | AO5: 預計 | AP5: 實際 | AQ5: 預計 | AR5: 實際 | AS5: 預計 | AT5: 實際 | AU5: 預計 | AV5: 實際 | AW5: 預計 | AX5: 實際 | AY5: 預計 | AZ5: 實際 | BA5: 預計 | BB5: 實際 | BC5: 預計 | BD5: 實際 | BE5: 預計 | BF5: 實際 | BG5: 預計 | BH5: 實際 | BI5: 預計 | BJ5: 實際 | BK5: 預計 | BL5: 實際 | BM5: 預計 | BN5: 實際 | BO5: 預計 | BP5: 實際 | BQ5: 預計 | BR5: 實際 | BS5: 預計 | BT5: 實際 | BU5: 預計 | BV5: 實際 | BW5: 預計 | BX5: 實際 | BY5: 預計 | BZ5: 實際 | CA5: 預計 | CB5: 實際 | CC5: 預計 | CD5: 實際 | CE5: 預計 | CF5: 實際 | CG5: 預計 | CH5: 實際 | CI5: 預計 | CJ5: 實際 | CK5: 預計 | CL5: 實際 | CM5: 預計 | CN5: 實際 | CO5: 預計 | CP5: 實際 | CQ5: 預計 | CR5: 實際 | CS5: 預計 | CT5: 實際 | CU5: 預計 | CV5: 實際 | CW5: 預計 | CX5: 實際 | CY5: 預計 | CZ5: 實際 | DA5: 預計 | DB5: 實際 | DC5: 預計 | DD5: 實際 | DE5: 預計 | DF5: 實際 | DG5: 預計 | DH5: 實際 | DI5: 預計 | DJ5: 實際 | DK5: 預計 | DL5: 實際 | DM5: 預計 | DN5: 實際 | DO5: 預計 | DP5: 實際 | DQ5: 預計 | DR5: 實際 | DS5: 預計 | DT5: 實際 | DU5: 預計 | DV5: 實際 | DW5: 預計 | DX5: 實際 | DY5: 預計 | DZ5: 實際 | EA5: 預計 | EB5: 實際 | EC5: 預計 | ED5: 實際
A6: ='PLM014'!A7 -> D-協同 | B6: D240902R1 | C6: ='PLM014'!C7 -> EPH結構改善與提升生產良率 | D6: ="("&B6&")"&" "&C6 -> (D240902R1) EPH結構改善與提升生產良率 | E6: ='PLM014'!E7 -> 產品開發 | F6: ='PLM014'!F7 -> 王瀚霆 | G6: ='PLM014'!G7 -> Active | H6: ='PLM014'!H7 -> 45557.667 | I6: ='PLM014'!I7 -> 45620.667 | J6: =IF(ISERROR(DATEDIF(H6,I6,"d")),"",DATEDIF(H6,I6,"d")) -> 63 | K6: =H6+(J6*0.75) -> 45604.917 | L6: =H6+(J6*0.95) -> 45617.517 | M6: =IF(ISERROR('PLM014'!L7),"",('PLM014'!L7)) -> 45558 | N6: =IF(IF(ISERROR('PLM014'!N7),"",('PLM014'!N7))=0,"",IF(ISERROR('PLM014'!N7),"",('PLM014'!N7))) | O6: =IF(ISERROR(DATEDIF(M6,N6,"d")),"",IF(DATEDIF(M6,N6,"d")=0,"",DATEDIF(M6,N6,"d"))) | P6: =IF(N6="",TODAY(),N6) -> 46044 | Q6: =IF(ISERROR(DATEDIF(M6,P6,"d")),"",IF(DATEDIF(M6,P6,"d")=0,"",DATEDIF(M6,P6,"d"))) -> 486 | R6: ='PLM014'!Q7/100 -> 0.97 | S6: =IF(AND(TODAY()>I6,R6<>100%,G6="Active"),"專案延遲 "&DATEDIF(I6,TODAY(),"d")&" 天",IF(AND(TODAY()>K6,R6<75%,G6="Active"),"專案即將異常",IF(AND(TODAY()>L6,R6<95%,G6="Active"),"專案即將異常",""))) -> 專案延遲 424 天 | U6: =IF(SUMIF($Y$5:$CV$5,$U$5,Y6:CV6)=0,"未登入",SUMIF($Y$5:$CV$5,$U$5,Y6:CV6)) -> 220 | V6: =SUMIF($Y$5:$CV$5,$V$5,Y6:CV6) -> 936.5 | W6: =IF(SUMIFS('PLM001-財務計算用'!$P:$P,'PLM001-財務計算用'!$A:$A,B6)=0,"未登入",SUMIFS('PLM001-財務計算用'!$P:$P,'PLM001-財務計算用'!$A:$A,B6)) -> 220 | X6: =SUMIFS('PLM002'!$K:$K,'PLM002'!$F:$F,$B6) -> 936.5 | Y6: =IF(SUMIFS('PLM001-財務計算用'!$P:$P,'PLM001-財務計算用'!$J:$J,Y$4,'PLM001-財務計算用'!$A:$A,$B6)=0,"",SUMIFS('PLM001-財務計算用'!$P:$P,'PLM001-財務計算用'!$J:$J,Y$4,'PLM001-財務計算用'!$A:$A,$B6)) | Z6: =IF(SUMIFS('PLM002'!$K:$K,'PLM002'!$C:$C,Y$4,'PLM002'!$F:$F,$B6)=0,"",SUMIFS('PLM002'!$K:$K,'PLM002'!$C:$C,Y$4,'PLM002'!$F:$F,$B6)) | AA6: =IF(SUMIFS('PLM001-財務計算用'!$P:$P,'PLM001-財務計算用'!$J:$J,AA$4,'PLM001-財務計算用'!$A:$A,$B6)=0,"",SUMIFS('PLM001-財務計算用'!$P:$P,'PLM001-財務計算用'!$J:$J,AA$4,'PLM001-財務計算用'!$A:$A,$B6)) | AB6: =IF(SUMIFS('PLM002'!$K:$K,'PLM002'!$C:$C,AA$4,'PLM002'!$F:$F,$B6)=0,"",SUMIFS('PLM002'!$K:$K,'PLM002'!$C:$C,AA$4,'PLM002'!$F:$F,$B6)) | AC6: =IF(SUMIFS('PLM001-財務計算用'!$P:$P,'PLM001-財務計算用'!$J:$J,AC$4,'PLM001-財務計算用'!$A:$A,$B6)=0,"",SUMIFS('PLM001-財務計算用'!$P:$P,'PLM001-財務計算用'!$J:$J,AC$4,'PLM001-財務計算用'!$A:$A,$B6)) | AD6: =IF(SUMIFS('PLM002'!$K:$K,'PLM002'!$C:$C,AC$4,'PLM002'!$F:$F,$B6)=0,"",SUMIFS('PLM002'!$K:$K,'PLM002'!$C:$C,AC$4,'PLM002'!$F:$F,$B6)) | AE6: =IF(SUMIFS('PLM001-財務計算用'!$P:$P,'PLM001-財務計算用'!$J:$J,AE$4,'PLM001-財務計算用'!$A:$A,$B6)=0,"",SUMIFS('PLM001-財務計算用'!$P:$P,'PLM001-財務計算用'!$J:$J,AE$4,'PLM001-財務計算用'!$A:$A,$B6)) | AF6: =IF(SUMIFS('PLM002'!$K:$K,'PLM002'!$C:$C,AE$4,'PLM002'!$F:$F,$B6)=0,"",SUMIFS('PLM002'!$K:$K,'PLM002'!$C:$C,AE$4,'PLM002'!$F:$F,$B6)) | AG6: =IF(SUMIFS('PLM001-財務計算用'!$P:$P,'PLM001-財務計算用'!$J:$J,AG$4,'PLM001-財務計算用'!$A:$A,$B6)=0,"",SUMIFS('PLM001-財務計算用'!$P:$P,'PLM001-財務計算用'!$J:$J,AG$4,'PLM001-財務計算用'!$A:$A,$B6)) | AH6: =IF(SUMIFS('PLM002'!$K:$K,'PLM002'!$C:$C,AG$4,'PLM002'!$F:$F,$B6)=0,"",SUMIFS('PLM002'!$K:$K,'PLM002'!$C:$C,AG$4,'PLM002'!$F:$F,$B6)) -> 13.5 | AI6: =IF(SUMIFS('PLM001-財務計算用'!$P:$P,'PLM001-財務計算用'!$J:$J,AI$4,'PLM001-財務計算用'!$A:$A,$B6)=0,"",SUMIFS('PLM001-財務計算用'!$P:$P,'PLM001-財務計算用'!$J:$J,AI$4,'PLM001-財務計算用'!$A:$A,$B6)) | AJ6: =IF(SUMIFS('PLM002'!$K:$K,'PLM002'!$C:$C,AI$4,'PLM002'!$F:$F,$B6)=0,"",SUMIFS('PLM002'!$K:$K,'PLM002'!$C:$C,AI$4,'PLM002'!$F:$F,$B6)) | AK6: =IF(SUMIFS('PLM001-財務計算用'!$P:$P,'PLM001-財務計算用'!$J:$J,AK$4,'PLM001-財務計算用'!$A:$A,$B6)=0,"",SUMIFS('PLM001-財務計算用'!$P:$P,'PLM001-財務計算用'!$J:$J,AK$4,'PLM001-財務計算用'!$A:$A,$B6)) | AL6: =IF(SUMIFS('PLM002'!$K:$K,'PLM002'!$C:$C,AK$4,'PLM002'!$F:$F,$B6)=0,"",SUMIFS('PLM002'!$K:$K,'PLM002'!$C:$C,AK$4,'PLM002'!$F:$F,$B6)) | AM6: =IF(SUMIFS('PLM001-財務計算用'!$P:$P,'PLM001-財務計算用'!$J:$J,AM$4,'PLM001-財務計算用'!$A:$A,$B6)=0,"",SUMIFS('PLM001-財務計算用'!$P:$P,'PLM001-財務計算用'!$J:$J,AM$4,'PLM001-財務計算用'!$A:$A,$B6)) | AN6: =IF(SUMIFS('PLM002'!$K:$K,'PLM002'!$C:$C,AM$4,'PLM002'!$F:$F,$B6)=0,"",SUMIFS('PLM002'!$K:$K,'PLM002'!$C:$C,AM$4,'PLM002'!$F:$F,$B6)) | AO6: =IF(SUMIFS('PLM001-財務計算用'!$P:$P,'PLM001-財務計算用'!$J:$J,AO$4,'PLM001-財務計算用'!$A:$A,$B6)=0,"",SUMIFS('PLM001-財務計算用'!$P:$P,'PLM001-財務計算用'!$J:$J,AO$4,'PLM001-財務計算用'!$A:$A,$B6)) | AP6: =IF(SUMIFS('PLM002'!$K:$K,'PLM002'!$C:$C,AO$4,'PLM002'!$F:$F,$B6)=0,"",SUMIFS('PLM002'!$K:$K,'PLM002'!$C:$C,AO$4,'PLM002'!$F:$F,$B6)) | AQ6: =IF(SUMIFS('PLM001-財務計算用'!$P:$P,'PLM001-財務計算用'!$J:$J,AQ$4,'PLM001-財務計算用'!$A:$A,$B6)=0,"",SUMIFS('PLM001-財務計算用'!$P:$P,'PLM001-財務計算用'!$J:$J,AQ$4,'PLM001-財務計算用'!$A:$A,$B6)) | AR6: =IF(SUMIFS('PLM002'!$K:$K,'PLM002'!$C:$C,AQ$4,'PLM002'!$F:$F,$B6)=0,"",SUMIFS('PLM002'!$K:$K,'PLM002'!$C:$C,AQ$4,'PLM002'!$F:$F,$B6)) | AS6: =IF(SUMIFS('PLM001-財務計算用'!$P:$P,'PLM001-財務計算用'!$J:$J,AS$4,'PLM001-財務計算用'!$A:$A,$B6)=0,"",SUMIFS('PLM001-財務計算用'!$P:$P,'PLM001-財務計算用'!$J:$J,AS$4,'PLM001-財務計算用'!$A:$A,$B6)) | AT6: =IF(SUMIFS('PLM002'!$K:$K,'PLM002'!$C:$C,AS$4,'PLM002'!$F:$F,$B6)=0,"",SUMIFS('PLM002'!$K:$K,'PLM002'!$C:$C,AS$4,'PLM002'!$F:$F,$B6)) | AU6: =IF(SUMIFS('PLM001-財務計算用'!$P:$P,'PLM001-財務計算用'!$J:$J,AU$4,'PLM001-財務計算用'!$A:$A,$B6)=0,"",SUMIFS('PLM001-財務計算用'!$P:$P,'PLM001-財務計算用'!$J:$J,AU$4,'PLM001-財務計算用'!$A:$A,$B6)) -> 80 | AV6: =IF(SUMIFS('PLM002'!$K:$K,'PLM002'!$C:$C,AU$4,'PLM002'!$F:$F,$B6)=0,"",SUMIFS('PLM002'!$K:$K,'PLM002'!$C:$C,AU$4,'PLM002'!$F:$F,$B6)) | AW6: =IF(SUMIFS('PLM001-財務計算用'!$P:$P,'PLM001-財務計算用'!$J:$J,AW$4,'PLM001-財務計算用'!$A:$A,$B6)=0,"",SUMIFS('PLM001-財務計算用'!$P:$P,'PLM001-財務計算用'!$J:$J,AW$4,'PLM001-財務計算用'!$A:$A,$B6)) | AX6: =IF(SUMIFS('PLM002'!$K:$K,'PLM002'!$C:$C,AW$4,'PLM002'!$F:$F,$B6)=0,"",SUMIFS('PLM002'!$K:$K,'PLM002'!$C:$C,AW$4,'PLM002'!$F:$F,$B6)) | AY6: =IF(SUMIFS('PLM001-財務計算用'!$P:$P,'PLM001-財務計算用'!$J:$J,AY$4,'PLM001-財務計算用'!$A:$A,$B6)=0,"",SUMIFS('PLM001-財務計算用'!$P:$P,'PLM001-財務計算用'!$J:$J,AY$4,'PLM001-財務計算用'!$A:$A,$B6)) | AZ6: =IF(SUMIFS('PLM002'!$K:$K,'PLM002'!$C:$C,AY$4,'PLM002'!$F:$F,$B6)=0,"",SUMIFS('PLM002'!$K:$K,'PLM002'!$C:$C,AY$4,'PLM002'!$F:$F,$B6)) | BA6: =IF(SUMIFS('PLM001-財務計算用'!$P:$P,'PLM001-財務計算用'!$J:$J,BA$4,'PLM001-財務計算用'!$A:$A,$B6)=0,"",SUMIFS('PLM001-財務計算用'!$P:$P,'PLM001-財務計算用'!$J:$J,BA$4,'PLM001-財務計算用'!$A:$A,$B6)) | BB6: =IF(SUMIFS('PLM002'!$K:$K,'PLM002'!$C:$C,BA$4,'PLM002'!$F:$F,$B6)=0,"",SUMIFS('PLM002'!$K:$K,'PLM002'!$C:$C,BA$4,'PLM002'!$F:$F,$B6)) | BC6: =IF(SUMIFS('PLM001-財務計算用'!$P:$P,'PLM001-財務計算用'!$J:$J,BC$4,'PLM001-財務計算用'!$A:$A,$B6)=0,"",SUMIFS('PLM001-財務計算用'!$P:$P,'PLM001-財務計算用'!$J:$J,BC$4,'PLM001-財務計算用'!$A:$A,$B6)) | BD6: =IF(SUMIFS('PLM002'!$K:$K,'PLM002'!$C:$C,BC$4,'PLM002'!$F:$F,$B6)=0,"",SUMIFS('PLM002'!$K:$K,'PLM002'!$C:$C,BC$4,'PLM002'!$F:$F,$B6)) | BE6: =IF(SUMIFS('PLM001-財務計算用'!$P:$P,'PLM001-財務計算用'!$J:$J,BE$4,'PLM001-財務計算用'!$A:$A,$B6)=0,"",SUMIFS('PLM001-財務計算用'!$P:$P,'PLM001-財務計算用'!$J:$J,BE$4,'PLM001-財務計算用'!$A:$A,$B6)) | BF6: =IF(SUMIFS('PLM002'!$K:$K,'PLM002'!$C:$C,BE$4,'PLM002'!$F:$F,$B6)=0,"",SUMIFS('PLM002'!$K:$K,'PLM002'!$C:$C,BE$4,'PLM002'!$F:$F,$B6)) | BG6: =IF(SUMIFS('PLM001-財務計算用'!$P:$P,'PLM001-財務計算用'!$J:$J,BG$4,'PLM001-財務計算用'!$A:$A,$B6)=0,"",SUMIFS('PLM001-財務計算用'!$P:$P,'PLM001-財務計算用'!$J:$J,BG$4,'PLM001-財務計算用'!$A:$A,$B6)) | BH6: =IF(SUMIFS('PLM002'!$K:$K,'PLM002'!$C:$C,BG$4,'PLM002'!$F:$F,$B6)=0,"",SUMIFS('PLM002'!$K:$K,'PLM002'!$C:$C,BG$4,'PLM002'!$F:$F,$B6)) | BI6: =IF(SUMIFS('PLM001-財務計算用'!$P:$P,'PLM001-財務計算用'!$J:$J,BI$4,'PLM001-財務計算用'!$A:$A,$B6)=0,"",SUMIFS('PLM001-財務計算用'!$P:$P,'PLM001-財務計算用'!$J:$J,BI$4,'PLM001-財務計算用'!$A:$A,$B6)) | BJ6: =IF(SUMIFS('PLM002'!$K:$K,'PLM002'!$C:$C,BI$4,'PLM002'!$F:$F,$B6)=0,"",SUMIFS('PLM002'!$K:$K,'PLM002'!$C:$C,BI$4,'PLM002'!$F:$F,$B6)) | BK6: =IF(SUMIFS('PLM001-財務計算用'!$P:$P,'PLM001-財務計算用'!$J:$J,BK$4,'PLM001-財務計算用'!$A:$A,$B6)=0,"",SUMIFS('PLM001-財務計算用'!$P:$P,'PLM001-財務計算用'!$J:$J,BK$4,'PLM001-財務計算用'!$A:$A,$B6)) | BL6: =IF(SUMIFS('PLM002'!$K:$K,'PLM002'!$C:$C,BK$4,'PLM002'!$F:$F,$B6)=0,"",SUMIFS('PLM002'!$K:$K,'PLM002'!$C:$C,BK$4,'PLM002'!$F:$F,$B6)) | BM6: =IF(SUMIFS('PLM001-財務計算用'!$P:$P,'PLM001-財務計算用'!$J:$J,BM$4,'PLM001-財務計算用'!$A:$A,$B6)=0,"",SUMIFS('PLM001-財務計算用'!$P:$P,'PLM001-財務計算用'!$J:$J,BM$4,'PLM001-財務計算用'!$A:$A,$B6)) | BN6: =IF(SUMIFS('PLM002'!$K:$K,'PLM002'!$C:$C,BM$4,'PLM002'!$F:$F,$B6)=0,"",SUMIFS('PLM002'!$K:$K,'PLM002'!$C:$C,BM$4,'PLM002'!$F:$F,$B6)) | BO6: =IF(SUMIFS('PLM001-財務計算用'!$P:$P,'PLM001-財務計算用'!$J:$J,BO$4,'PLM001-財務計算用'!$A:$A,$B6)=0,"",SUMIFS('PLM001-財務計算用'!$P:$P,'PLM001-財務計算用'!$J:$J,BO$4,'PLM001-財務計算用'!$A:$A,$B6)) | BP6: =IF(SUMIFS('PLM002'!$K:$K,'PLM002'!$C:$C,BO$4,'PLM002'!$F:$F,$B6)=0,"",SUMIFS('PLM002'!$K:$K,'PLM002'!$C:$C,BO$4,'PLM002'!$F:$F,$B6)) | BQ6: =IF(SUMIFS('PLM001-財務計算用'!$P:$P,'PLM001-財務計算用'!$J:$J,BQ$4,'PLM001-財務計算用'!$A:$A,$B6)=0,"",SUMIFS('PLM001-財務計算用'!$P:$P,'PLM001-財務計算用'!$J:$J,BQ$4,'PLM001-財務計算用'!$A:$A,$B6)) | BR6: =IF(SUMIFS('PLM002'!$K:$K,'PLM002'!$C:$C,BQ$4,'PLM002'!$F:$F,$B6)=0,"",SUMIFS('PLM002'!$K:$K,'PLM002'!$C:$C,BQ$4,'PLM002'!$F:$F,$B6)) | BS6: =IF(SUMIFS('PLM001-財務計算用'!$P:$P,'PLM001-財務計算用'!$J:$J,BS$4,'PLM001-財務計算用'!$A:$A,$B6)=0,"",SUMIFS('PLM001-財務計算用'!$P:$P,'PLM001-財務計算用'!$J:$J,BS$4,'PLM001-財務計算用'!$A:$A,$B6)) -> 116 | BT6: =IF(SUMIFS('PLM002'!$K:$K,'PLM002'!$C:$C,BS$4,'PLM002'!$F:$F,$B6)=0,"",SUMIFS('PLM002'!$K:$K,'PLM002'!$C:$C,BS$4,'PLM002'!$F:$F,$B6)) -> 818.5 | BU6: =IF(SUMIFS('PLM001-財務計算用'!$P:$P,'PLM001-財務計算用'!$J:$J,BU$4,'PLM001-財務計算用'!$A:$A,$B6)=0,"",SUMIFS('PLM001-財務計算用'!$P:$P,'PLM001-財務計算用'!$J:$J,BU$4,'PLM001-財務計算用'!$A:$A,$B6)) | BV6: =IF(SUMIFS('PLM002'!$K:$K,'PLM002'!$C:$C,BU$4,'PLM002'!$F:$F,$B6)=0,"",SUMIFS('PLM002'!$K:$K,'PLM002'!$C:$C,BU$4,'PLM002'!$F:$F,$B6)) -> 18.5 | BW6: =IF(SUMIFS('PLM001-財務計算用'!$P:$P,'PLM001-財務計算用'!$J:$J,BW$4,'PLM001-財務計算用'!$A:$A,$B6)=0,"",SUMIFS('PLM001-財務計算用'!$P:$P,'PLM001-財務計算用'!$J:$J,BW$4,'PLM001-財務計算用'!$A:$A,$B6)) | BX6: =IF(SUMIFS('PLM002'!$K:$K,'PLM002'!$C:$C,BW$4,'PLM002'!$F:$F,$B6)=0,"",SUMIFS('PLM002'!$K:$K,'PLM002'!$C:$C,BW$4,'PLM002'!$F:$F,$B6)) -> 86 | BY6: =IF(SUMIFS('PLM001-財務計算用'!$P:$P,'PLM001-財務計算用'!$J:$J,BY$4,'PLM001-財務計算用'!$A:$A,$B6)=0,"",SUMIFS('PLM001-財務計算用'!$P:$P,'PLM001-財務計算用'!$J:$J,BY$4,'PLM001-財務計算用'!$A:$A,$B6)) | BZ6: =IF(SUMIFS('PLM002'!$K:$K,'PLM002'!$C:$C,BY$4,'PLM002'!$F:$F,$B6)=0,"",SUMIFS('PLM002'!$K:$K,'PLM002'!$C:$C,BY$4,'PLM002'!$F:$F,$B6)) | CA6: =IF(SUMIFS('PLM001-財務計算用'!$P:$P,'PLM001-財務計算用'!$J:$J,CA$4,'PLM001-財務計算用'!$A:$A,$B6)=0,"",SUMIFS('PLM001-財務計算用'!$P:$P,'PLM001-財務計算用'!$J:$J,CA$4,'PLM001-財務計算用'!$A:$A,$B6)) | CB6: =IF(SUMIFS('PLM002'!$K:$K,'PLM002'!$C:$C,CA$4,'PLM002'!$F:$F,$B6)=0,"",SUMIFS('PLM002'!$K:$K,'PLM002'!$C:$C,CA$4,'PLM002'!$F:$F,$B6)) | CC6: =IF(SUMIFS('PLM001-財務計算用'!$P:$P,'PLM001-財務計算用'!$J:$J,CC$4,'PLM001-財務計算用'!$A:$A,$B6)=0,"",SUMIFS('PLM001-財務計算用'!$P:$P,'PLM001-財務計算用'!$J:$J,CC$4,'PLM001-財務計算用'!$A:$A,$B6)) | CD6: =IF(SUMIFS('PLM002'!$K:$K,'PLM002'!$C:$C,CC$4,'PLM002'!$F:$F,$B6)=0,"",SUMIFS('PLM002'!$K:$K,'PLM002'!$C:$C,CC$4,'PLM002'!$F:$F,$B6)) | CE6: =IF(SUMIFS('PLM001-財務計算用'!$P:$P,'PLM001-財務計算用'!$J:$J,CE$4,'PLM001-財務計算用'!$A:$A,$B6)=0,"",SUMIFS('PLM001-財務計算用'!$P:$P,'PLM001-財務計算用'!$J:$J,CE$4,'PLM001-財務計算用'!$A:$A,$B6)) | CF6: =IF(SUMIFS('PLM002'!$K:$K,'PLM002'!$C:$C,CE$4,'PLM002'!$F:$F,$B6)=0,"",SUMIFS('PLM002'!$K:$K,'PLM002'!$C:$C,CE$4,'PLM002'!$F:$F,$B6)) | CG6: =IF(SUMIFS('PLM001-財務計算用'!$P:$P,'PLM001-財務計算用'!$J:$J,CG$4,'PLM001-財務計算用'!$A:$A,$B6)=0,"",SUMIFS('PLM001-財務計算用'!$P:$P,'PLM001-財務計算用'!$J:$J,CG$4,'PLM001-財務計算用'!$A:$A,$B6)) | CH6: =IF(SUMIFS('PLM002'!$K:$K,'PLM002'!$C:$C,CG$4,'PLM002'!$F:$F,$B6)=0,"",SUMIFS('PLM002'!$K:$K,'PLM002'!$C:$C,CG$4,'PLM002'!$F:$F,$B6)) | CI6: =IF(SUMIFS('PLM001-財務計算用'!$P:$P,'PLM001-財務計算用'!$J:$J,CI$4,'PLM001-財務計算用'!$A:$A,$B6)=0,"",SUMIFS('PLM001-財務計算用'!$P:$P,'PLM001-財務計算用'!$J:$J,CI$4,'PLM001-財務計算用'!$A:$A,$B6)) | CJ6: =IF(SUMIFS('PLM002'!$K:$K,'PLM002'!$C:$C,CI$4,'PLM002'!$F:$F,$B6)=0,"",SUMIFS('PLM002'!$K:$K,'PLM002'!$C:$C,CI$4,'PLM002'!$F:$F,$B6)) | CK6: =IF(SUMIFS('PLM001-財務計算用'!$P:$P,'PLM001-財務計算用'!$J:$J,CK$4,'PLM001-財務計算用'!$A:$A,$B6)=0,"",SUMIFS('PLM001-財務計算用'!$P:$P,'PLM001-財務計算用'!$J:$J,CK$4,'PLM001-財務計算用'!$A:$A,$B6)) | CL6: =IF(SUMIFS('PLM002'!$K:$K,'PLM002'!$C:$C,CK$4,'PLM002'!$F:$F,$B6)=0,"",SUMIFS('PLM002'!$K:$K,'PLM002'!$C:$C,CK$4,'PLM002'!$F:$F,$B6)) | CM6: =IF(SUMIFS('PLM001-財務計算用'!$P:$P,'PLM001-財務計算用'!$J:$J,CM$4,'PLM001-財務計算用'!$A:$A,$B6)=0,"",SUMIFS('PLM001-財務計算用'!$P:$P,'PLM001-財務計算用'!$J:$J,CM$4,'PLM001-財務計算用'!$A:$A,$B6)) | CN6: =IF(SUMIFS('PLM002'!$K:$K,'PLM002'!$C:$C,CM$4,'PLM002'!$F:$F,$B6)=0,"",SUMIFS('PLM002'!$K:$K,'PLM002'!$C:$C,CM$4,'PLM002'!$F:$F,$B6)) | CO6: =IF(SUMIFS('PLM001-財務計算用'!$P:$P,'PLM001-財務計算用'!$J:$J,CO$4,'PLM001-財務計算用'!$A:$A,$B6)=0,"",SUMIFS('PLM001-財務計算用'!$P:$P,'PLM001-財務計算用'!$J:$J,CO$4,'PLM001-財務計算用'!$A:$A,$B6)) | CP6: =IF(SUMIFS('PLM002'!$K:$K,'PLM002'!$C:$C,CO$4,'PLM002'!$F:$F,$B6)=0,"",SUMIFS('PLM002'!$K:$K,'PLM002'!$C:$C,CO$4,'PLM002'!$F:$F,$B6)) | CQ6: =IF(SUMIFS('PLM001-財務計算用'!$P:$P,'PLM001-財務計算用'!$J:$J,CQ$4,'PLM001-財務計算用'!$A:$A,$B6)=0,"",SUMIFS('PLM001-財務計算用'!$P:$P,'PLM001-財務計算用'!$J:$J,CQ$4,'PLM001-財務計算用'!$A:$A,$B6)) | CR6: =IF(SUMIFS('PLM002'!$K:$K,'PLM002'!$C:$C,CQ$4,'PLM002'!$F:$F,$B6)=0,"",SUMIFS('PLM002'!$K:$K,'PLM002'!$C:$C,CQ$4,'PLM002'!$F:$F,$B6)) | CS6: =IF(SUMIFS('PLM001-財務計算用'!$P:$P,'PLM001-財務計算用'!$J:$J,CS$4,'PLM001-財務計算用'!$A:$A,$B6)=0,"",SUMIFS('PLM001-財務計算用'!$P:$P,'PLM001-財務計算用'!$J:$J,CS$4,'PLM001-財務計算用'!$A:$A,$B6)) -> 24 | CT6: =IF(SUMIFS('PLM002'!$K:$K,'PLM002'!$C:$C,CS$4,'PLM002'!$F:$F,$B6)=0,"",SUMIFS('PLM002'!$K:$K,'PLM002'!$C:$C,CS$4,'PLM002'!$F:$F,$B6)) | CU6: =IF(SUMIFS('PLM001-財務計算用'!$P:$P,'PLM001-財務計算用'!$J:$J,CU$4,'PLM001-財務計算用'!$A:$A,$B6)=0,"",SUMIFS('PLM001-財務計算用'!$P:$P,'PLM001-財務計算用'!$J:$J,CU$4,'PLM001-財務計算用'!$A:$A,$B6)) | CV6: =IF(SUMIFS('PLM002'!$K:$K,'PLM002'!$C:$C,CU$4,'PLM002'!$F:$F,$B6)=0,"",SUMIFS('PLM002'!$K:$K,'PLM002'!$C:$C,CU$4,'PLM002'!$F:$F,$B6)) | CW6: =IF(SUMIFS('PLM001-財務計算用'!$P:$P,'PLM001-財務計算用'!$J:$J,CW$4,'PLM001-財務計算用'!$A:$A,$B6)=0,"",SUMIFS('PLM001-財務計算用'!$P:$P,'PLM001-財務計算用'!$J:$J,CW$4,'PLM001-財務計算用'!$A:$A,$B6)) | CX6: =IF(SUMIFS('PLM002'!$K:$K,'PLM002'!$C:$C,CW$4,'PLM002'!$F:$F,$B6)=0,"",SUMIFS('PLM002'!$K:$K,'PLM002'!$C:$C,CW$4,'PLM002'!$F:$F,$B6)) | CY6: =IF(SUMIFS('PLM001-財務計算用'!$P:$P,'PLM001-財務計算用'!$J:$J,CY$4,'PLM001-財務計算用'!$A:$A,$B6)=0,"",SUMIFS('PLM001-財務計算用'!$P:$P,'PLM001-財務計算用'!$J:$J,CY$4,'PLM001-財務計算用'!$A:$A,$B6)) | CZ6: =IF(SUMIFS('PLM002'!$K:$K,'PLM002'!$C:$C,CY$4,'PLM002'!$F:$F,$B6)=0,"",SUMIFS('PLM002'!$K:$K,'PLM002'!$C:$C,CY$4,'PLM002'!$F:$F,$B6)) | DA6: =IF(SUMIFS('PLM001-財務計算用'!$P:$P,'PLM001-財務計算用'!$J:$J,DA$4,'PLM001-財務計算用'!$A:$A,$B6)=0,"",SUMIFS('PLM001-財務計算用'!$P:$P,'PLM001-財務計算用'!$J:$J,DA$4,'PLM001-財務計算用'!$A:$A,$B6)) | DB6: =IF(SUMIFS('PLM002'!$K:$K,'PLM002'!$C:$C,DA$4,'PLM002'!$F:$F,$B6)=0,"",SUMIFS('PLM002'!$K:$K,'PLM002'!$C:$C,DA$4,'PLM002'!$F:$F,$B6)) | DC6: =IF(SUMIFS('PLM001-財務計算用'!$P:$P,'PLM001-財務計算用'!$J:$J,DC$4,'PLM001-財務計算用'!$A:$A,$B6)=0,"",SUMIFS('PLM001-財務計算用'!$P:$P,'PLM001-財務計算用'!$J:$J,DC$4,'PLM001-財務計算用'!$A:$A,$B6)) | DD6: =IF(SUMIFS('PLM002'!$K:$K,'PLM002'!$C:$C,DC$4,'PLM002'!$F:$F,$B6)=0,"",SUMIFS('PLM002'!$K:$K,'PLM002'!$C:$C,DC$4,'PLM002'!$F:$F,$B6)) | DE6: =IF(SUMIFS('PLM001-財務計算用'!$P:$P,'PLM001-財務計算用'!$J:$J,DE$4,'PLM001-財務計算用'!$A:$A,$B6)=0,"",SUMIFS('PLM001-財務計算用'!$P:$P,'PLM001-財務計算用'!$J:$J,DE$4,'PLM001-財務計算用'!$A:$A,$B6)) | DF6: =IF(SUMIFS('PLM002'!$K:$K,'PLM002'!$C:$C,DE$4,'PLM002'!$F:$F,$B6)=0,"",SUMIFS('PLM002'!$K:$K,'PLM002'!$C:$C,DE$4,'PLM002'!$F:$F,$B6)) | DG6: =IF(SUMIFS('PLM001-財務計算用'!$P:$P,'PLM001-財務計算用'!$J:$J,DG$4,'PLM001-財務計算用'!$A:$A,$B6)=0,"",SUMIFS('PLM001-財務計算用'!$P:$P,'PLM001-財務計算用'!$J:$J,DG$4,'PLM001-財務計算用'!$A:$A,$B6)) | DH6: =IF(SUMIFS('PLM002'!$K:$K,'PLM002'!$C:$C,DG$4,'PLM002'!$F:$F,$B6)=0,"",SUMIFS('PLM002'!$K:$K,'PLM002'!$C:$C,DG$4,'PLM002'!$F:$F,$B6)) | DI6: =IF(SUMIFS('PLM001-財務計算用'!$P:$P,'PLM001-財務計算用'!$J:$J,DI$4,'PLM001-財務計算用'!$A:$A,$B6)=0,"",SUMIFS('PLM001-財務計算用'!$P:$P,'PLM001-財務計算用'!$J:$J,DI$4,'PLM001-財務計算用'!$A:$A,$B6)) | DJ6: =IF(SUMIFS('PLM002'!$K:$K,'PLM002'!$C:$C,DI$4,'PLM002'!$F:$F,$B6)=0,"",SUMIFS('PLM002'!$K:$K,'PLM002'!$C:$C,DI$4,'PLM002'!$F:$F,$B6)) | DK6: =IF(SUMIFS('PLM001-財務計算用'!$P:$P,'PLM001-財務計算用'!$J:$J,DK$4,'PLM001-財務計算用'!$A:$A,$B6)=0,"",SUMIFS('PLM001-財務計算用'!$P:$P,'PLM001-財務計算用'!$J:$J,DK$4,'PLM001-財務計算用'!$A:$A,$B6)) | DL6: =IF(SUMIFS('PLM002'!$K:$K,'PLM002'!$C:$C,DK$4,'PLM002'!$F:$F,$B6)=0,"",SUMIFS('PLM002'!$K:$K,'PLM002'!$C:$C,DK$4,'PLM002'!$F:$F,$B6)) | DM6: =IF(SUMIFS('PLM001-財務計算用'!$P:$P,'PLM001-財務計算用'!$J:$J,DM$4,'PLM001-財務計算用'!$A:$A,$B6)=0,"",SUMIFS('PLM001-財務計算用'!$P:$P,'PLM001-財務計算用'!$J:$J,DM$4,'PLM001-財務計算用'!$A:$A,$B6)) | DN6: =IF(SUMIFS('PLM002'!$K:$K,'PLM002'!$C:$C,DM$4,'PLM002'!$F:$F,$B6)=0,"",SUMIFS('PLM002'!$K:$K,'PLM002'!$C:$C,DM$4,'PLM002'!$F:$F,$B6)) | DO6: =IF(SUMIFS('PLM001-財務計算用'!$P:$P,'PLM001-財務計算用'!$J:$J,DO$4,'PLM001-財務計算用'!$A:$A,$B6)=0,"",SUMIFS('PLM001-財務計算用'!$P:$P,'PLM001-財務計算用'!$J:$J,DO$4,'PLM001-財務計算用'!$A:$A,$B6)) | DP6: =IF(SUMIFS('PLM002'!$K:$K,'PLM002'!$C:$C,DO$4,'PLM002'!$F:$F,$B6)=0,"",SUMIFS('PLM002'!$K:$K,'PLM002'!$C:$C,DO$4,'PLM002'!$F:$F,$B6)) | DQ6: =IF(SUMIFS('PLM001-財務計算用'!$P:$P,'PLM001-財務計算用'!$J:$J,DQ$4,'PLM001-財務計算用'!$A:$A,$B6)=0,"",SUMIFS('PLM001-財務計算用'!$P:$P,'PLM001-財務計算用'!$J:$J,DQ$4,'PLM001-財務計算用'!$A:$A,$B6)) | DR6: =IF(SUMIFS('PLM002'!$K:$K,'PLM002'!$C:$C,DQ$4,'PLM002'!$F:$F,$B6)=0,"",SUMIFS('PLM002'!$K:$K,'PLM002'!$C:$C,DQ$4,'PLM002'!$F:$F,$B6)) | DS6: =IF(SUMIFS('PLM001-財務計算用'!$P:$P,'PLM001-財務計算用'!$J:$J,DS$4,'PLM001-財務計算用'!$A:$A,$B6)=0,"",SUMIFS('PLM001-財務計算用'!$P:$P,'PLM001-財務計算用'!$J:$J,DS$4,'PLM001-財務計算用'!$A:$A,$B6)) | DT6: =IF(SUMIFS('PLM002'!$K:$K,'PLM002'!$C:$C,DS$4,'PLM002'!$F:$F,$B6)=0,"",SUMIFS('PLM002'!$K:$K,'PLM002'!$C:$C,DS$4,'PLM002'!$F:$F,$B6)) | DU6: =IF(SUMIFS('PLM001-財務計算用'!$P:$P,'PLM001-財務計算用'!$J:$J,DU$4,'PLM001-財務計算用'!$A:$A,$B6)=0,"",SUMIFS('PLM001-財務計算用'!$P:$P,'PLM001-財務計算用'!$J:$J,DU$4,'PLM001-財務計算用'!$A:$A,$B6)) | DV6: =IF(SUMIFS('PLM002'!$K:$K,'PLM002'!$C:$C,DU$4,'PLM002'!$F:$F,$B6)=0,"",SUMIFS('PLM002'!$K:$K,'PLM002'!$C:$C,DU$4,'PLM002'!$F:$F,$B6)) | DW6: =IF(SUMIFS('PLM001-財務計算用'!$P:$P,'PLM001-財務計算用'!$J:$J,DW$4,'PLM001-財務計算用'!$A:$A,$B6)=0,"",SUMIFS('PLM001-財務計算用'!$P:$P,'PLM001-財務計算用'!$J:$J,DW$4,'PLM001-財務計算用'!$A:$A,$B6)) | DX6: =IF(SUMIFS('PLM002'!$K:$K,'PLM002'!$C:$C,DW$4,'PLM002'!$F:$F,$B6)=0,"",SUMIFS('PLM002'!$K:$K,'PLM002'!$C:$C,DW$4,'PLM002'!$F:$F,$B6)) | DY6: =IF(SUMIFS('PLM001-財務計算用'!$P:$P,'PLM001-財務計算用'!$J:$J,DY$4,'PLM001-財務計算用'!$A:$A,$B6)=0,"",SUMIFS('PLM001-財務計算用'!$P:$P,'PLM001-財務計算用'!$J:$J,DY$4,'PLM001-財務計算用'!$A:$A,$B6)) | DZ6: =IF(SUMIFS('PLM002'!$K:$K,'PLM002'!$C:$C,DY$4,'PLM002'!$F:$F,$B6)=0,"",SUMIFS('PLM002'!$K:$K,'PLM002'!$C:$C,DY$4,'PLM002'!$F:$F,$B6)) | EA6: =IF(SUMIFS('PLM001-財務計算用'!$P:$P,'PLM001-財務計算用'!$J:$J,EA$4,'PLM001-財務計算用'!$A:$A,$B6)=0,"",SUMIFS('PLM001-財務計算用'!$P:$P,'PLM001-財務計算用'!$J:$J,EA$4,'PLM001-財務計算用'!$A:$A,$B6)) | EB6: =IF(SUMIFS('PLM002'!$K:$K,'PLM002'!$C:$C,EA$4,'PLM002'!$F:$F,$B6)=0,"",SUMIFS('PLM002'!$K:$K,'PLM002'!$C:$C,EA$4,'PLM002'!$F:$F,$B6)) | EC6: =IF(SUMIFS('PLM001-財務計算用'!$P:$P,'PLM001-財務計算用'!$J:$J,EC$4,'PLM001-財務計算用'!$A:$A,$B6)=0,"",SUMIFS('PLM001-財務計算用'!$P:$P,'PLM001-財務計算用'!$J:$J,EC$4,'PLM001-財務計算用'!$A:$A,$B6)) | ED6: =IF(SUMIFS('PLM002'!$K:$K,'PLM002'!$C:$C,EC$4,'PLM002'!$F:$F,$B6)=0,"",SUMIFS('PLM002'!$K:$K,'PLM002'!$C:$C,EC$4,'PLM002'!$F:$F,$B6))
